Workbook

Sheet Notes
A1: 附件使用说明
A3: 项目 | B3: 说明
A4: 整体用途 | B4: 本工作簿是赛题“面向智慧社区的多无人机—物业人员联合巡检优化”的修订平衡版附件，可直接用于问题1与问题2求解。
A5: 问题1所需数据 | B5: NodeData、FlightTime、FlightEnergy、UAV_Params。
A6: 问题2所需数据 | B6: 在问题1基础上再使用 ManualPoints、GroundTime；问题2中直接使用 direct_confirm_time_s 作为无人机直接确认所需累计停留时间阈值。
A7: 节点定义 | B7: node_id=0 为服务中心；node_id=1~16 为巡检目标点。每次无人机任务都从 0 出发并回到 0。
A8: 中心位置说明 | B8: 社区服务中心与物业服务中心同址；附件中无人机起点记为 node_id=0，物业复核起点记为 P0，二者坐标一致。
A9: 运营时长约束范围 | B9: operating_horizon_s 用于约束无人机阶段总作业时长；物业复核耗时计入闭环总完成时间 T=T_u+T_g，但不再受 operating_horizon_s 直接限制。
A10: 累计停留时间 | B10: 同一目标点允许被同一架或不同架无人机重复巡检；某目标点的累计停留时间 T_s 为所有访问该点停留时间之和。
A11: 问题1判定 | B11: 若目标点 s 满足 T_s >= base_hover_time_s，则该点完成基础空中巡检。
A12: 问题2判定 | B12: 若目标点 s 满足 T_s >= direct_confirm_time_s，则该点由无人机直接确认；否则需要物业复核。
A13: 单次任务能耗 | B13: 单次任务总能耗 = 路径飞行能耗之和 + hover_power_J_per_s × 停留时间之和，应不超过 effective_energy_limit_J。
A14: 单次任务时间 | B14: 单次任务总时间 = 路径飞行时间之和 + 停留时间之和；多次任务之间若返航换电，还需加 battery_swap_time_s。
... A16: 数据性质 | B16: 本附件已将部分高难度点的 direct_confirm_time_s 上调，并适度收紧 operating_horizon_s，以增强问题2的联合优化张力。

Sheet UAV_Params
A1: 无人机与运营参数
A3: parameter | B3: value | C3: unit | D3: meaning
A4: K_max | B4: 4 | C4: 架 | D4: 候选无人机最大数量，上题可比较 K=1~4
A5: battery_capacity_J | B5: 160000 | C5: J | D5: 单次出航电池容量
A6: safety_reserve_J | B6: 25000 | C6: J | D6: 返航与安全余量
A7: effective_energy_limit_J | B7: =B5-B6 -> 135000 | C7: J | D7: 建议作为单次任务能耗上限
A8: horizontal_speed_mps | B8: 12 | C8: m/s | D8: 水平飞行速度
A9: vertical_speed_mps | B9: 4 | C9: m/s | D9: 垂直升降速度
A10: horizontal_energy_J_per_m | B10: 16.5 | C10: J/m | D10: 水平飞行单位距离能耗
A11: up_energy_J_per_m | B11: 23 | C11: J/m | D11: 上升单位距离能耗
A12: down_energy_J_per_m | B12: 12 | C12: J/m | D12: 下降单位距离能耗
A13: hover_power_J_per_s | B13: 220 | C13: J/s | D13: 悬停观测单位时间能耗
A14: battery_swap_time_s | B14: 300 | C14: s | D14: 返航更换电池时间
A15: operating_horizon_s | B15: 2600 | C15: s | D15: 全天允许的总作业时长
A16: walking_speed_mps | B16: 1.35 | C16: m/s | D16: 物业步行速度
A17: walking_detour_factor | B17: 1.25 | C17: - | D17: 地面绕行系数

Sheet NodeData
A1: 节点与目标点数据
A3: node_id | B3: node_name | C3: building_id | D3: x_m | E3: y_m | F3: z_m | G3: priority_level | H3: priority_weight | I3: issue_type | J3: base_hover_time_s | K3: direct_confirm_time_s | L3: extra_confirm_time_s | M3: manual_point_id | N3: manual_x_m | O3: manual_y_m | P3: manual_service_time_s | Q3: direct_out_back_flight_energy_J | R3: direct_base_roundtrip_total_energy_J | S3: direct_confirm_roundtrip_total_energy_J | T3: remarks
A4: 0 | B4: 社区服务中心 | C4: DEPOT | D4: 0 | E4: 0 | F4: 0 | G4: 核心 | H4: 0 | I4: 起降点 | J4: 0 | K4: 0 | L4: 0 | M4: P0 | N4: 0 | O4: 0 | P4: 0 | Q4: 0 | R4: 0 | S4: 0 | T4: 无人机起降与换电点
A5: 1 | B5: B1-东立面裂缝 | C5: B1 | D5: 92 | E5: 148 | F5: 18 | G5: 中 | H5: 2 | I5: 立面裂缝 | J5: 50 | K5: 200 | L5: =K5-J5 -> 150 | M5: MP01 | N5: 92 | O5: 148 | P5: 180 | Q5: =FlightEnergy!$D$4+FlightEnergy!$C$5 -> 6380 | R5: =Q5+J5*UAV_Params!$B$13 -> 17380 | S5: =Q5+K5*UAV_Params!$B$13 -> 50380 | T5: 靠近东南角
A6: 2 | B6: B1-屋顶积水 | C6: B1 | D6: 78 | E6: 138 | F6: 31 | G6: 高 | H6: 3 | I6: 排水异常 | J6: 60 | K6: 520 | L6: =K6-J6 -> 460 | M6: MP02 | N6: 78 | O6: 138 | P6: 180 | Q6: =FlightEnergy!$E$4+FlightEnergy!$C$6 -> 6317 | R6: =Q6+J6*UAV_Params!$B$13 -> 19517 | S6: =Q6+K6*UAV_Params!$B$13 -> 120717 | T6: 雨后优先复核；无人机直接确认门槛较高
A7: 3 | B7: B1-消防连廊顶部 | C7: B1 | D7: 84 | E7: 126 | F7: 24 | G7: 低 | H7: 1 | I7: 附属设施 | J7: 35 | K7: 110 | L7: =K7-J7 -> 75 | M7: MP03 | N7: 84 | O7: 126 | P7: 120 | Q7: =FlightEnergy!$F$4+FlightEnergy!$C$7 -> 5838 | R7: =Q7+J7*UAV_Params!$B$13 -> 13538 | S7: =Q7+K7*UAV_Params!$B$13 -> 30038 | T7: 例行巡查
A8: 4 | B8: B2-空调支架锈蚀 | C8: B2 | D8: 158 | E8: 68 | F8: 20 | G8: 中 | H8: 2 | I8: 金属锈蚀 | J8: 55 | K8: 240 | L8: =K8-J8 -> 185 | M8: MP04 | N8: 158 | O8: 68 | P8: 180 | Q8: =FlightEnergy!$G$4+FlightEnergy!$C$8 -> 6376 | R8: =Q8+J8*UAV_Params!$B$13 -> 18476 | S8: =Q8+K8*UAV_Params!$B$13 -> 59176 | T8: 住户投诉点
A9: 5 | B9: B2-屋面排水口堵塞 | C9: B2 | D9: 146 | E9: 82 | F9: 34 | G9: 高 | H9: 3 | I9: 排水异常 | J9: 50 | K9: 420 | L9: =K9-J9 -> 370 | M9: MP05 | N9: 146 | O9: 82 | P9: 180 | Q9: =FlightEnergy!$H$4+FlightEnergy!$C$9 -> 6716 | R9: =Q9+J9*UAV_Params!$B$13 -> 17716 | S9: =Q9+K9*UAV_Params!$B$13 -> 99116 | T9: 排水类问题需更长观测时间
A10: 6 | B10: B2-北立面瓷砖鼓包 | C10: B2 | D10: 172 | E10: 54 | F10: 16 | G10: 中 | H10: 2 | I10: 外立面风险 | J10: 40 | K10: 180 | L10: =K10-J10 -> 140 | M10: MP06 | N10: 172 | O10: 54 | P10: 150 | Q10: =FlightEnergy!$I$4+FlightEnergy!$C$10 -> 6510 | R10: =Q10+J10*UAV_Params!$B$13 -> 15310 | S10: =Q10+K10*UAV_Params!$B$13 -> 46110 | T10: 需近距离确认
A11: 7 | B11: B3-西侧窗框松动 | C11: B3 | D11: 206 | E11: -36 | F11: 22 | G11: 中 | H11: 2 | I11: 构件松动 | J11: 45 | K11: 200 | L11: =K11-J11 -> 155 | M11: MP07 | N11: 206 | O11: -36 | P11: 150 | Q11: =FlightEnergy!$J$4+FlightEnergy!$C$11 -> 7672 | R11: =Q11+J11*UAV_Params!$B$13 -> 17572 | S11: =Q11+K11*UAV_Params!$B$13 -> 51672 | T11: 风大时优先
A12: 8 | B12: B3-屋顶通信箱体 | C12: B3 | D12: 194 | E12: -22 | F12: 36 | G12: 高 | H12: 3 | I12: 设备异常 | J12: 60 | K12: 560 | L12: =K12-J12 -> 500 | M12: MP08 | N12: 194 | O12: -22 | P12: 180 | Q12: =FlightEnergy!$K$4+FlightEnergy!$C$12 -> 7704 | R12: =Q12+J12*UAV_Params!$B$13 -> 20904 | S12: =Q12+K12*UAV_Params!$B$13 -> 130904 | T12: 设备异常识别困难，建议与人工复核比较
A13: 9 | B13: B4-南外墙脱落点 | C13: B4 | D13: 46 | E13: -128 | F13: 17 | G13: 高 | H13: 3 | I13: 外立面风险 | J13: 55 | K13: 520 | L13: =K13-J13 -> 465 | M13: MP09 | N13: 46 | O13: -128 | P13: 180 | Q13: =FlightEnergy!$L$4+FlightEnergy!$C$13 -> 5083 | R13: =Q13+J13*UAV_Params!$B$13 -> 17183 | S13: =Q13+K13*UAV_Params!$B$13 -> 119483 | T13: 高风险脱落点，建议比较空地分工
A14: 10 | B14: B4-屋顶天沟堆积 | C14: B4 | D14: 56 | E14: -116 | F14: 30 | G14: 中 | H14: 2 | I14: 排水异常 | J14: 45 | K14: 190 | L14: =K14-J14 -> 145 | M14: MP10 | N14: 56 | O14: -116 | P14: 180 | Q14: =FlightEnergy!$M$4+FlightEnergy!$C$14 -> 5300 | R14: =Q14+J14*UAV_Params!$B$13 -> 15200 | S14: =Q14+K14*UAV_Params!$B$13 -> 47100 | T14: 清运后复检
A15: 11 | B15: B5-屋顶消防标识遮挡 | C15: B5 | D15: -84 | E15: -154 | F15: 25 | G15: 低 | H15: 1 | I15: 标识问题 | J15: 35 | K15: 110 | L15: =K15-J15 -> 75 | M15: MP11 | N15: -84 | O15: -154 | P15: 120 | Q15: =FlightEnergy!$N$4+FlightEnergy!$C$15 -> 6663 | R15: =Q15+J15*UAV_Params!$B$13 -> 14363 | S15: =Q15+K15*UAV_Params!$B$13 -> 30863 | T15: 例行巡查
A16: 12 | B16: B5-东侧外挂线缆 | C16: B5 | D16: -72 | E16: -144 | F16: 12 | G16: 中 | H16: 2 | I16: 线缆异常 | J16: 40 | K16: 170 | L16: =K16-J16 -> 130 | M16: MP12 | N16: -72 | O16: -144 | P16: 150 | Q16: =FlightEnergy!$O$4+FlightEnergy!$C$16 -> 5732 | R16: =Q16+J16*UAV_Params!$B$13 -> 14532 | S16: =Q16+K16*UAV_Params!$B$13 -> 43132 | T16: 需到场确认
A17: 13 | B17: B6-屋顶空调机组异常 | C17: B6 | D17: -148 | E17: 46 | F17: 24 | G17: 高 | H17: 3 | I17: 设备异常 | J17: 60 | K17: 540 | L17: =K17-J17 -> 480 | M17: MP13 | N17: -148 | O17: 46 | P17: 180 | Q17: =FlightEnergy!$P$4+FlightEnergy!$C$17 -> 5954 | R17: =Q17+J17*UAV_Params!$B$13 -> 19154 | S17: =Q17+K17*UAV_Params!$B$13 -> 124754 | T17: 设备异常识别困难，阈值上调
A18: 14 | B18: B6-西立面渗水痕迹 | C18: B6 | D18: -162 | E18: 58 | F18: 18 | G18: 中 | H18: 2 | I18: 渗漏风险 | J18: 50 | K18: 330 | L18: =K18-J18 -> 280 | M18: MP14 | N18: -162 | O18: 58 | P18: 180 | Q18: =FlightEnergy!$Q$4+FlightEnergy!$C$18 -> 6308 | R18: =Q18+J18*UAV_Params!$B$13 -> 17308 | S18: =Q18+K18*UAV_Params!$B$13 -> 78908 | T18: 雨天后易复发
A19: 15 | B19: B7-光伏棚支架松动 | C19: B7 | D19: -204 | E19: 162 | F19: 22 | G19: 中 | H19: 2 | I19: 构件松动 | J19: 45 | K19: 360 | L19: =K19-J19 -> 315 | M19: MP15 | N19: -204 | O19: 162 | P19: 180 | Q19: =FlightEnergy!$R$4+FlightEnergy!$C$19 -> 9366 | R19: =Q19+J19*UAV_Params!$B$13 -> 19266 | S19: =Q19+K19*UAV_Params!$B$13 -> 88566 | T19: 需结合地面查看
A20: 16 | B20: B7-屋顶围挡破损 | C20: B7 | D20: -192 | E20: 176 | F20: 34 | G20: 高 | H20: 3 | I20: 屋顶构件 | J20: 65 | K20: 560 | L20: =K20-J20 -> 495 | M20: MP16 | N20: -192 | O20: 176 | P20: 180 | Q20: =FlightEnergy!$S$4+FlightEnergy!$C$20 -> 9786 | R20: =Q20+J20*UAV_Params!$B$13 -> 24086 | S20: =Q20+K20*UAV_Params!$B$13 -> 132986 | T20: 高风险屋顶构件，直接确认门槛最高

Sheet ManualPoints
A1: 物业复核点数据
A3: manual_point_id | B3: mapped_target_id | C3: x_m | D3: y_m | E3: manual_service_time_s | F3: issue_type | G3: note
A4: P0 | B4: 0 | C4: 0 | D4: 0 | E4: 0 | F4: 物业服务中心 | G4: 物业出发与返回点
A5: MP01 | B5: 1 | C5: 92 | D5: 148 | E5: 180 | F5: 立面裂缝 | G5: B1-东立面裂缝
A6: MP02 | B6: 2 | C6: 78 | D6: 138 | E6: 210 | F6: 排水异常 | G6: B1-屋顶积水
A7: MP03 | B7: 3 | C7: 84 | D7: 126 | E7: 120 | F7: 附属设施 | G7: B1-消防连廊顶部
A8: MP04 | B8: 4 | C8: 158 | D8: 68 | E8: 180 | F8: 金属锈蚀 | G8: B2-空调支架锈蚀
A9: MP05 | B9: 5 | C9: 146 | D9: 82 | E9: 180 | F9: 排水异常 | G9: B2-屋面排水口堵塞
A10: MP06 | B10: 6 | C10: 172 | D10: 54 | E10: 150 | F10: 外立面风险 | G10: B2-北立面瓷砖鼓包
A11: MP07 | B11: 7 | C11: 206 | D11: -36 | E11: 150 | F11: 构件松动 | G11: B3-西侧窗框松动
A12: MP08 | B12: 8 | C12: 194 | D12: -22 | E12: 240 | F12: 设备异常 | G12: B3-屋顶通信箱体
A13: MP09 | B13: 9 | C13: 46 | D13: -128 | E13: 240 | F13: 外立面风险 | G13: B4-南外墙脱落点
A14: MP10 | B14: 10 | C14: 56 | D14: -116 | E14: 180 | F14: 排水异常 | G14: B4-屋顶天沟堆积
A15: MP11 | B15: 11 | C15: -84 | D15: -154 | E15: 120 | F15: 标识问题 | G15: B5-屋顶消防标识遮挡
... A20: MP16 | B20: 16 | C20: -192 | D20: 176 | E20: 240 | F20: 屋顶构件 | G20: B7-屋顶围挡破损

Sheet FlightTime
A1: 节点间飞行时间矩阵（秒）
A3: from_id | B3: from_name | C3: 0 | D3: 1 | E3: 2 | F3: 3 | G3: 4 | H3: 5 | I3: 6 | J3: 7 | K3: 8 | L3: 9 | M3: 10 | N3: 11 | O3: 12 | P3: 13 | Q3: 14 | R3: 15 | S3: 16
A4: 0 | B4: 社区服务中心 | C4: =IF($A4=C$3,0,ROUND(SQRT((NodeData!$D4-NodeData!$D4)^2+(NodeData!$E4-NodeData!$E4)^2)/UAV_Params!$B$8+ABS(NodeData!$F4-NodeData!$F4)/UAV_Params!$B$9,1)) -> 0 | D4: =IF($A4=D$3,0,ROUND(SQRT((NodeData!$D4-NodeData!$D5)^2+(NodeData!$E4-NodeData!$E5)^2)/UAV_Params!$B$8+ABS(NodeData!$F4-NodeData!$F5)/UAV_Params!$B$9,1)) -> 19 | E4: =IF($A4=E$3,0,ROUND(SQRT((NodeData!$D4-NodeData!$D6)^2+(NodeData!$E4-NodeData!$E6)^2)/UAV_Params!$B$8+ABS(NodeData!$F4-NodeData!$F6)/UAV_Params!$B$9,1)) -> 21 | F4: =IF($A4=F$3,0,ROUND(SQRT((NodeData!$D4-NodeData!$D7)^2+(NodeData!$E4-NodeData!$E7)^2)/UAV_Params!$B$8+ABS(NodeData!$F4-NodeData!$F7)/UAV_Params!$B$9,1)) -> 18.6 | G4: =IF($A4=G$3,0,ROUND(SQRT((NodeData!$D4-NodeData!$D8)^2+(NodeData!$E4-NodeData!$E8)^2)/UAV_Params!$B$8+ABS(NodeData!$F4-NodeData!$F8)/UAV_Params!$B$9,1)) -> 19.3 | H4: =IF($A4=H$3,0,ROUND(SQRT((NodeData!$D4-NodeData!$D9)^2+(NodeData!$E4-NodeData!$E9)^2)/UAV_Params!$B$8+ABS(NodeData!$F4-NodeData!$F9)/UAV_Params!$B$9,1)) -> 22.5 | I4: =IF($A4=I$3,0,ROUND(SQRT((NodeData!$D4-NodeData!$D10)^2+(NodeData!$E4-NodeData!$E10)^2)/UAV_Params!$B$8+ABS(NodeData!$F4-NodeData!$F10)/UAV_Params!$B$9,1)) -> 19 | J4: =IF($A4=J$3,0,ROUND(SQRT((NodeData!$D4-NodeData!$D11)^2+(NodeData!$E4-NodeData!$E11)^2)/UAV_Params!$B$8+ABS(NodeData!$F4-NodeData!$F11)/UAV_Params!$B$9,1)) -> 22.9 | K4: =IF($A4=K$3,0,ROUND(SQRT((NodeData!$D4-NodeData!$D12)^2+(NodeData!$E4-NodeData!$E12)^2)/UAV_Params!$B$8+ABS(NodeData!$F4-NodeData!$F12)/UAV_Params!$B$9,1)) -> 25.3 | L4: =IF($A4=L$3,0,ROUND(SQRT((NodeData!$D4-NodeData!$D13)^2+(NodeData!$E4-NodeData!$E13)^2)/UAV_Params!$B$8+ABS(NodeData!$F4-NodeData!$F13)/UAV_Params!$B$9,1)) -> 15.6 | M4: =IF($A4=M$3,0,ROUND(SQRT((NodeData!$D4-NodeData!$D14)^2+(NodeData!$E4-NodeData!$E14)^2)/UAV_Params!$B$8+ABS(NodeData!$F4-NodeData!$F14)/UAV_Params!$B$9,1)) -> 18.2 | N4: =IF($A4=N$3,0,ROUND(SQRT((NodeData!$D4-NodeData!$D15)^2+(NodeData!$E4-NodeData!$E15)^2)/UAV_Params!$B$8+ABS(NodeData!$F4-NodeData!$F15)/UAV_Params!$B$9,1)) -> 20.9 | O4: =IF($A4=O$3,0,ROUND(SQRT((NodeData!$D4-NodeData!$D16)^2+(NodeData!$E4-NodeData!$E16)^2)/UAV_Params!$B$8+ABS(NodeData!$F4-NodeData!$F16)/UAV_Params!$B$9,1)) -> 16.4 | P4: =IF($A4=P$3,0,ROUND(SQRT((NodeData!$D4-NodeData!$D17)^2+(NodeData!$E4-NodeData!$E17)^2)/UAV_Params!$B$8+ABS(NodeData!$F4-NodeData!$F17)/UAV_Params!$B$9,1)) -> 18.9 | Q4: =IF($A4=Q$3,0,ROUND(SQRT((NodeData!$D4-NodeData!$D18)^2+(NodeData!$E4-NodeData!$E18)^2)/UAV_Params!$B$8+ABS(NodeData!$F4-NodeData!$F18)/UAV_Params!$B$9,1)) -> 18.8 | R4: =IF($A4=R$3,0,ROUND(SQRT((NodeData!$D4-NodeData!$D19)^2+(NodeData!$E4-NodeData!$E19)^2)/UAV_Params!$B$8+ABS(NodeData!$F4-NodeData!$F19)/UAV_Params!$B$9,1)) -> 27.2 | S4: =IF($A4=S$3,0,ROUND(SQRT((NodeData!$D4-NodeData!$D20)^2+(NodeData!$E4-NodeData!$E20)^2)/UAV_Params!$B$8+ABS(NodeData!$F4-NodeData!$F20)/UAV_Params!$B$9,1)) -> 30.2
A5: 1 | B5: B1-东立面裂缝 | C5: =IF($A5=C$3,0,ROUND(SQRT((NodeData!$D5-NodeData!$D4)^2+(NodeData!$E5-NodeData!$E4)^2)/UAV_Params!$B$8+ABS(NodeData!$F5-NodeData!$F4)/UAV_Params!$B$9,1)) -> 19 | D5: =IF($A5=D$3,0,ROUND(SQRT((NodeData!$D5-NodeData!$D5)^2+(NodeData!$E5-NodeData!$E5)^2)/UAV_Params!$B$8+ABS(NodeData!$F5-NodeData!$F5)/UAV_Params!$B$9,1)) -> 0 | E5: =IF($A5=E$3,0,ROUND(SQRT((NodeData!$D5-NodeData!$D6)^2+(NodeData!$E5-NodeData!$E6)^2)/UAV_Params!$B$8+ABS(NodeData!$F5-NodeData!$F6)/UAV_Params!$B$9,1)) -> 4.7 | F5: =IF($A5=F$3,0,ROUND(SQRT((NodeData!$D5-NodeData!$D7)^2+(NodeData!$E5-NodeData!$E7)^2)/UAV_Params!$B$8+ABS(NodeData!$F5-NodeData!$F7)/UAV_Params!$B$9,1)) -> 3.5 | G5: =IF($A5=G$3,0,ROUND(SQRT((NodeData!$D5-NodeData!$D8)^2+(NodeData!$E5-NodeData!$E8)^2)/UAV_Params!$B$8+ABS(NodeData!$F5-NodeData!$F8)/UAV_Params!$B$9,1)) -> 9.1 | H5: =IF($A5=H$3,0,ROUND(SQRT((NodeData!$D5-NodeData!$D9)^2+(NodeData!$E5-NodeData!$E9)^2)/UAV_Params!$B$8+ABS(NodeData!$F5-NodeData!$F9)/UAV_Params!$B$9,1)) -> 11.1 | I5: =IF($A5=I$3,0,ROUND(SQRT((NodeData!$D5-NodeData!$D10)^2+(NodeData!$E5-NodeData!$E10)^2)/UAV_Params!$B$8+ABS(NodeData!$F5-NodeData!$F10)/UAV_Params!$B$9,1)) -> 10.8 | J5: =IF($A5=J$3,0,ROUND(SQRT((NodeData!$D5-NodeData!$D11)^2+(NodeData!$E5-NodeData!$E11)^2)/UAV_Params!$B$8+ABS(NodeData!$F5-NodeData!$F11)/UAV_Params!$B$9,1)) -> 19 | K5: =IF($A5=K$3,0,ROUND(SQRT((NodeData!$D5-NodeData!$D12)^2+(NodeData!$E5-NodeData!$E12)^2)/UAV_Params!$B$8+ABS(NodeData!$F5-NodeData!$F12)/UAV_Params!$B$9,1)) -> 21 | L5: =IF($A5=L$3,0,ROUND(SQRT((NodeData!$D5-NodeData!$D13)^2+(NodeData!$E5-NodeData!$E13)^2)/UAV_Params!$B$8+ABS(NodeData!$F5-NodeData!$F13)/UAV_Params!$B$9,1)) -> 23.6 | M5: =IF($A5=M$3,0,ROUND(SQRT((NodeData!$D5-NodeData!$D14)^2+(NodeData!$E5-NodeData!$E14)^2)/UAV_Params!$B$8+ABS(NodeData!$F5-NodeData!$F14)/UAV_Params!$B$9,1)) -> 25.2 | N5: =IF($A5=N$3,0,ROUND(SQRT((NodeData!$D5-NodeData!$D15)^2+(NodeData!$E5-NodeData!$E15)^2)/UAV_Params!$B$8+ABS(NodeData!$F5-NodeData!$F15)/UAV_Params!$B$9,1)) -> 30.9 | O5: =IF($A5=O$3,0,ROUND(SQRT((NodeData!$D5-NodeData!$D16)^2+(NodeData!$E5-NodeData!$E16)^2)/UAV_Params!$B$8+ABS(NodeData!$F5-NodeData!$F16)/UAV_Params!$B$9,1)) -> 29.4 | P5: =IF($A5=P$3,0,ROUND(SQRT((NodeData!$D5-NodeData!$D17)^2+(NodeData!$E5-NodeData!$E17)^2)/UAV_Params!$B$8+ABS(NodeData!$F5-NodeData!$F17)/UAV_Params!$B$9,1)) -> 23.2 | Q5: =IF($A5=Q$3,0,ROUND(SQRT((NodeData!$D5-NodeData!$D18)^2+(NodeData!$E5-NodeData!$E18)^2)/UAV_Params!$B$8+ABS(NodeData!$F5-NodeData!$F18)/UAV_Params!$B$9,1)) -> 22.5 | R5: =IF($A5=R$3,0,ROUND(SQRT((NodeData!$D5-NodeData!$D19)^2+(NodeData!$E5-NodeData!$E19)^2)/UAV_Params!$B$8+ABS(NodeData!$F5-NodeData!$F19)/UAV_Params!$B$9,1)) -> 25.7 | S5: =IF($A5=S$3,0,ROUND(SQRT((NodeData!$D5-NodeData!$D20)^2+(NodeData!$E5-NodeData!$E20)^2)/UAV_Params!$B$8+ABS(NodeData!$F5-NodeData!$F20)/UAV_Params!$B$9,1)) -> 27.8
A6: 2 | B6: B1-屋顶积水 | C6: =IF($A6=C$3,0,ROUND(SQRT((NodeData!$D6-NodeData!$D4)^2+(NodeData!$E6-NodeData!$E4)^2)/UAV_Params!$B$8+ABS(NodeData!$F6-NodeData!$F4)/UAV_Params!$B$9,1)) -> 21 | D6: =IF($A6=D$3,0,ROUND(SQRT((NodeData!$D6-NodeData!$D5)^2+(NodeData!$E6-NodeData!$E5)^2)/UAV_Params!$B$8+ABS(NodeData!$F6-NodeData!$F5)/UAV_Params!$B$9,1)) -> 4.7 | E6: =IF($A6=E$3,0,ROUND(SQRT((NodeData!$D6-NodeData!$D6)^2+(NodeData!$E6-NodeData!$E6)^2)/UAV_Params!$B$8+ABS(NodeData!$F6-NodeData!$F6)/UAV_Params!$B$9,1)) -> 0 | F6: =IF($A6=F$3,0,ROUND(SQRT((NodeData!$D6-NodeData!$D7)^2+(NodeData!$E6-NodeData!$E7)^2)/UAV_Params!$B$8+ABS(NodeData!$F6-NodeData!$F7)/UAV_Params!$B$9,1)) -> 2.9 | G6: =IF($A6=G$3,0,ROUND(SQRT((NodeData!$D6-NodeData!$D8)^2+(NodeData!$E6-NodeData!$E8)^2)/UAV_Params!$B$8+ABS(NodeData!$F6-NodeData!$F8)/UAV_Params!$B$9,1)) -> 11.6 | H6: =IF($A6=H$3,0,ROUND(SQRT((NodeData!$D6-NodeData!$D9)^2+(NodeData!$E6-NodeData!$E9)^2)/UAV_Params!$B$8+ABS(NodeData!$F6-NodeData!$F9)/UAV_Params!$B$9,1)) -> 8.1 | I6: =IF($A6=I$3,0,ROUND(SQRT((NodeData!$D6-NodeData!$D10)^2+(NodeData!$E6-NodeData!$E10)^2)/UAV_Params!$B$8+ABS(NodeData!$F6-NodeData!$F10)/UAV_Params!$B$9,1)) -> 14.3 | J6: =IF($A6=J$3,0,ROUND(SQRT((NodeData!$D6-NodeData!$D11)^2+(NodeData!$E6-NodeData!$E11)^2)/UAV_Params!$B$8+ABS(NodeData!$F6-NodeData!$F11)/UAV_Params!$B$9,1)) -> 20.3 | K6: =IF($A6=K$3,0,ROUND(SQRT((NodeData!$D6-NodeData!$D12)^2+(NodeData!$E6-NodeData!$E12)^2)/UAV_Params!$B$8+ABS(NodeData!$F6-NodeData!$F12)/UAV_Params!$B$9,1)) -> 17.7 | L6: =IF($A6=L$3,0,ROUND(SQRT((NodeData!$D6-NodeData!$D13)^2+(NodeData!$E6-NodeData!$E13)^2)/UAV_Params!$B$8+ABS(NodeData!$F6-NodeData!$F13)/UAV_Params!$B$9,1)) -> 25.8 | M6: =IF($A6=M$3,0,ROUND(SQRT((NodeData!$D6-NodeData!$D14)^2+(NodeData!$E6-NodeData!$E14)^2)/UAV_Params!$B$8+ABS(NodeData!$F6-NodeData!$F14)/UAV_Params!$B$9,1)) -> 21.5 | N6: =IF($A6=N$3,0,ROUND(SQRT((NodeData!$D6-NodeData!$D15)^2+(NodeData!$E6-NodeData!$E15)^2)/UAV_Params!$B$8+ABS(NodeData!$F6-NodeData!$F15)/UAV_Params!$B$9,1)) -> 29.3 | O6: =IF($A6=O$3,0,ROUND(SQRT((NodeData!$D6-NodeData!$D16)^2+(NodeData!$E6-NodeData!$E16)^2)/UAV_Params!$B$8+ABS(NodeData!$F6-NodeData!$F16)/UAV_Params!$B$9,1)) -> 31.4 | P6: =IF($A6=P$3,0,ROUND(SQRT((NodeData!$D6-NodeData!$D17)^2+(NodeData!$E6-NodeData!$E17)^2)/UAV_Params!$B$8+ABS(NodeData!$F6-NodeData!$F17)/UAV_Params!$B$9,1)) -> 22.1 | Q6: =IF($A6=Q$3,0,ROUND(SQRT((NodeData!$D6-NodeData!$D18)^2+(NodeData!$E6-NodeData!$E18)^2)/UAV_Params!$B$8+ABS(NodeData!$F6-NodeData!$F18)/UAV_Params!$B$9,1)) -> 24.3 | R6: =IF($A6=R$3,0,ROUND(SQRT((NodeData!$D6-NodeData!$D19)^2+(NodeData!$E6-NodeData!$E19)^2)/UAV_Params!$B$8+ABS(NodeData!$F6-NodeData!$F19)/UAV_Params!$B$9,1)) -> 25.8 | S6: =IF($A6=S$3,0,ROUND(SQRT((NodeData!$D6-NodeData!$D20)^2+(NodeData!$E6-NodeData!$E20)^2)/UAV_Params!$B$8+ABS(NodeData!$F6-NodeData!$F20)/UAV_Params!$B$9,1)) -> 23.5
A7: 3 | B7: B1-消防连廊顶部 | C7: =IF($A7=C$3,0,ROUND(SQRT((NodeData!$D7-NodeData!$D4)^2+(NodeData!$E7-NodeData!$E4)^2)/UAV_Params!$B$8+ABS(NodeData!$F7-NodeData!$F4)/UAV_Params!$B$9,1)) -> 18.6 | D7: =IF($A7=D$3,0,ROUND(SQRT((NodeData!$D7-NodeData!$D5)^2+(NodeData!$E7-NodeData!$E5)^2)/UAV_Params!$B$8+ABS(NodeData!$F7-NodeData!$F5)/UAV_Params!$B$9,1)) -> 3.5 | E7: =IF($A7=E$3,0,ROUND(SQRT((NodeData!$D7-NodeData!$D6)^2+(NodeData!$E7-NodeData!$E6)^2)/UAV_Params!$B$8+ABS(NodeData!$F7-NodeData!$F6)/UAV_Params!$B$9,1)) -> 2.9 | F7: =IF($A7=F$3,0,ROUND(SQRT((NodeData!$D7-NodeData!$D7)^2+(NodeData!$E7-NodeData!$E7)^2)/UAV_Params!$B$8+ABS(NodeData!$F7-NodeData!$F7)/UAV_Params!$B$9,1)) -> 0 | G7: =IF($A7=G$3,0,ROUND(SQRT((NodeData!$D7-NodeData!$D8)^2+(NodeData!$E7-NodeData!$E8)^2)/UAV_Params!$B$8+ABS(NodeData!$F7-NodeData!$F8)/UAV_Params!$B$9,1)) -> 8.8 | H7: =IF($A7=H$3,0,ROUND(SQRT((NodeData!$D7-NodeData!$D9)^2+(NodeData!$E7-NodeData!$E9)^2)/UAV_Params!$B$8+ABS(NodeData!$F7-NodeData!$F9)/UAV_Params!$B$9,1)) -> 8.8 | I7: =IF($A7=I$3,0,ROUND(SQRT((NodeData!$D7-NodeData!$D10)^2+(NodeData!$E7-NodeData!$E10)^2)/UAV_Params!$B$8+ABS(NodeData!$F7-NodeData!$F10)/UAV_Params!$B$9,1)) -> 11.5 | J7: =IF($A7=J$3,0,ROUND(SQRT((NodeData!$D7-NodeData!$D11)^2+(NodeData!$E7-NodeData!$E11)^2)/UAV_Params!$B$8+ABS(NodeData!$F7-NodeData!$F11)/UAV_Params!$B$9,1)) -> 17.4 | K7: =IF($A7=K$3,0,ROUND(SQRT((NodeData!$D7-NodeData!$D12)^2+(NodeData!$E7-NodeData!$E12)^2)/UAV_Params!$B$8+ABS(NodeData!$F7-NodeData!$F12)/UAV_Params!$B$9,1)) -> 18.4 | L7: =IF($A7=L$3,0,ROUND(SQRT((NodeData!$D7-NodeData!$D13)^2+(NodeData!$E7-NodeData!$E13)^2)/UAV_Params!$B$8+ABS(NodeData!$F7-NodeData!$F13)/UAV_Params!$B$9,1)) -> 23.2 | M7: =IF($A7=M$3,0,ROUND(SQRT((NodeData!$D7-NodeData!$D14)^2+(NodeData!$E7-NodeData!$E14)^2)/UAV_Params!$B$8+ABS(NodeData!$F7-NodeData!$F14)/UAV_Params!$B$9,1)) -> 21.8 | N7: =IF($A7=N$3,0,ROUND(SQRT((NodeData!$D7-NodeData!$D15)^2+(NodeData!$E7-NodeData!$E15)^2)/UAV_Params!$B$8+ABS(NodeData!$F7-NodeData!$F15)/UAV_Params!$B$9,1)) -> 27.5 | O7: =IF($A7=O$3,0,ROUND(SQRT((NodeData!$D7-NodeData!$D16)^2+(NodeData!$E7-NodeData!$E16)^2)/UAV_Params!$B$8+ABS(NodeData!$F7-NodeData!$F16)/UAV_Params!$B$9,1)) -> 29 | P7: =IF($A7=P$3,0,ROUND(SQRT((NodeData!$D7-NodeData!$D17)^2+(NodeData!$E7-NodeData!$E17)^2)/UAV_Params!$B$8+ABS(NodeData!$F7-NodeData!$F17)/UAV_Params!$B$9,1)) -> 20.5 | Q7: =IF($A7=Q$3,0,ROUND(SQRT((NodeData!$D7-NodeData!$D18)^2+(NodeData!$E7-NodeData!$E18)^2)/UAV_Params!$B$8+ABS(NodeData!$F7-NodeData!$F18)/UAV_Params!$B$9,1)) -> 22.8 | R7: =IF($A7=R$3,0,ROUND(SQRT((NodeData!$D7-NodeData!$D19)^2+(NodeData!$E7-NodeData!$E19)^2)/UAV_Params!$B$8+ABS(NodeData!$F7-NodeData!$F19)/UAV_Params!$B$9,1)) -> 24.7 | S7: =IF($A7=S$3,0,ROUND(SQRT((NodeData!$D7-NodeData!$D20)^2+(NodeData!$E7-NodeData!$E20)^2)/UAV_Params!$B$8+ABS(NodeData!$F7-NodeData!$F20)/UAV_Params!$B$9,1)) -> 25.9
A8: 4 | B8: B2-空调支架锈蚀 | C8: =IF($A8=C$3,0,ROUND(SQRT((NodeData!$D8-NodeData!$D4)^2+(NodeData!$E8-NodeData!$E4)^2)/UAV_Params!$B$8+ABS(NodeData!$F8-NodeData!$F4)/UAV_Params!$B$9,1)) -> 19.3 | D8: =IF($A8=D$3,0,ROUND(SQRT((NodeData!$D8-NodeData!$D5)^2+(NodeData!$E8-NodeData!$E5)^2)/UAV_Params!$B$8+ABS(NodeData!$F8-NodeData!$F5)/UAV_Params!$B$9,1)) -> 9.1 | E8: =IF($A8=E$3,0,ROUND(SQRT((NodeData!$D8-NodeData!$D6)^2+(NodeData!$E8-NodeData!$E6)^2)/UAV_Params!$B$8+ABS(NodeData!$F8-NodeData!$F6)/UAV_Params!$B$9,1)) -> 11.6 | F8: =IF($A8=F$3,0,ROUND(SQRT((NodeData!$D8-NodeData!$D7)^2+(NodeData!$E8-NodeData!$E7)^2)/UAV_Params!$B$8+ABS(NodeData!$F8-NodeData!$F7)/UAV_Params!$B$9,1)) -> 8.8 | G8: =IF($A8=G$3,0,ROUND(SQRT((NodeData!$D8-NodeData!$D8)^2+(NodeData!$E8-NodeData!$E8)^2)/UAV_Params!$B$8+ABS(NodeData!$F8-NodeData!$F8)/UAV_Params!$B$9,1)) -> 0 | H8: =IF($A8=H$3,0,ROUND(SQRT((NodeData!$D8-NodeData!$D9)^2+(NodeData!$E8-NodeData!$E9)^2)/UAV_Params!$B$8+ABS(NodeData!$F8-NodeData!$F9)/UAV_Params!$B$9,1)) -> 5 | I8: =IF($A8=I$3,0,ROUND(SQRT((NodeData!$D8-NodeData!$D10)^2+(NodeData!$E8-NodeData!$E10)^2)/UAV_Params!$B$8+ABS(NodeData!$F8-NodeData!$F10)/UAV_Params!$B$9,1)) -> 2.6 | J8: =IF($A8=J$3,0,ROUND(SQRT((NodeData!$D8-NodeData!$D11)^2+(NodeData!$E8-NodeData!$E11)^2)/UAV_Params!$B$8+ABS(NodeData!$F8-NodeData!$F11)/UAV_Params!$B$9,1)) -> 10 | K8: =IF($A8=K$3,0,ROUND(SQRT((NodeData!$D8-NodeData!$D12)^2+(NodeData!$E8-NodeData!$E12)^2)/UAV_Params!$B$8+ABS(NodeData!$F8-NodeData!$F12)/UAV_Params!$B$9,1)) -> 12.1 | L8: =IF($A8=L$3,0,ROUND(SQRT((NodeData!$D8-NodeData!$D13)^2+(NodeData!$E8-NodeData!$E13)^2)/UAV_Params!$B$8+ABS(NodeData!$F8-NodeData!$F13)/UAV_Params!$B$9,1)) -> 19.6 | M8: =IF($A8=M$3,0,ROUND(SQRT((NodeData!$D8-NodeData!$D14)^2+(NodeData!$E8-NodeData!$E14)^2)/UAV_Params!$B$8+ABS(NodeData!$F8-NodeData!$F14)/UAV_Params!$B$9,1)) -> 20 | N8: =IF($A8=N$3,0,ROUND(SQRT((NodeData!$D8-NodeData!$D15)^2+(NodeData!$E8-NodeData!$E15)^2)/UAV_Params!$B$8+ABS(NodeData!$F8-NodeData!$F15)/UAV_Params!$B$9,1)) -> 28.6 | O8: =IF($A8=O$3,0,ROUND(SQRT((NodeData!$D8-NodeData!$D16)^2+(NodeData!$E8-NodeData!$E16)^2)/UAV_Params!$B$8+ABS(NodeData!$F8-NodeData!$F16)/UAV_Params!$B$9,1)) -> 28.1 | P8: =IF($A8=P$3,0,ROUND(SQRT((NodeData!$D8-NodeData!$D17)^2+(NodeData!$E8-NodeData!$E17)^2)/UAV_Params!$B$8+ABS(NodeData!$F8-NodeData!$F17)/UAV_Params!$B$9,1)) -> 26.6 | Q8: =IF($A8=Q$3,0,ROUND(SQRT((NodeData!$D8-NodeData!$D18)^2+(NodeData!$E8-NodeData!$E18)^2)/UAV_Params!$B$8+ABS(NodeData!$F8-NodeData!$F18)/UAV_Params!$B$9,1)) -> 27.2 | R8: =IF($A8=R$3,0,ROUND(SQRT((NodeData!$D8-NodeData!$D19)^2+(NodeData!$E8-NodeData!$E19)^2)/UAV_Params!$B$8+ABS(NodeData!$F8-NodeData!$F19)/UAV_Params!$B$9,1)) -> 31.7 | S8: =IF($A8=S$3,0,ROUND(SQRT((NodeData!$D8-NodeData!$D20)^2+(NodeData!$E8-NodeData!$E20)^2)/UAV_Params!$B$8+ABS(NodeData!$F8-NodeData!$F20)/UAV_Params!$B$9,1)) -> 34
A9: 5 | B9: B2-屋面排水口堵塞 | C9: =IF($A9=C$3,0,ROUND(SQRT((NodeData!$D9-NodeData!$D4)^2+(NodeData!$E9-NodeData!$E4)^2)/UAV_Params!$B$8+ABS(NodeData!$F9-NodeData!$F4)/UAV_Params!$B$9,1)) -> 22.5 | D9: =IF($A9=D$3,0,ROUND(SQRT((NodeData!$D9-NodeData!$D5)^2+(NodeData!$E9-NodeData!$E5)^2)/UAV_Params!$B$8+ABS(NodeData!$F9-NodeData!$F5)/UAV_Params!$B$9,1)) -> 11.1 | E9: =IF($A9=E$3,0,ROUND(SQRT((NodeData!$D9-NodeData!$D6)^2+(NodeData!$E9-NodeData!$E6)^2)/UAV_Params!$B$8+ABS(NodeData!$F9-NodeData!$F6)/UAV_Params!$B$9,1)) -> 8.1 | F9: =IF($A9=F$3,0,ROUND(SQRT((NodeData!$D9-NodeData!$D7)^2+(NodeData!$E9-NodeData!$E7)^2)/UAV_Params!$B$8+ABS(NodeData!$F9-NodeData!$F7)/UAV_Params!$B$9,1)) -> 8.8 | G9: =IF($A9=G$3,0,ROUND(SQRT((NodeData!$D9-NodeData!$D8)^2+(NodeData!$E9-NodeData!$E8)^2)/UAV_Params!$B$8+ABS(NodeData!$F9-NodeData!$F8)/UAV_Params!$B$9,1)) -> 5 | H9: =IF($A9=H$3,0,ROUND(SQRT((NodeData!$D9-NodeData!$D9)^2+(NodeData!$E9-NodeData!$E9)^2)/UAV_Params!$B$8+ABS(NodeData!$F9-NodeData!$F9)/UAV_Params!$B$9,1)) -> 0 | I9: =IF($A9=I$3,0,ROUND(SQRT((NodeData!$D9-NodeData!$D10)^2+(NodeData!$E9-NodeData!$E10)^2)/UAV_Params!$B$8+ABS(NodeData!$F9-NodeData!$F10)/UAV_Params!$B$9,1)) -> 7.7 | J9: =IF($A9=J$3,0,ROUND(SQRT((NodeData!$D9-NodeData!$D11)^2+(NodeData!$E9-NodeData!$E11)^2)/UAV_Params!$B$8+ABS(NodeData!$F9-NodeData!$F11)/UAV_Params!$B$9,1)) -> 14 | K9: =IF($A9=K$3,0,ROUND(SQRT((NodeData!$D9-NodeData!$D12)^2+(NodeData!$E9-NodeData!$E12)^2)/UAV_Params!$B$8+ABS(NodeData!$F9-NodeData!$F12)/UAV_Params!$B$9,1)) -> 10 | L9: =IF($A9=L$3,0,ROUND(SQRT((NodeData!$D9-NodeData!$D13)^2+(NodeData!$E9-NodeData!$E13)^2)/UAV_Params!$B$8+ABS(NodeData!$F9-NodeData!$F13)/UAV_Params!$B$9,1)) -> 23.6 | M9: =IF($A9=M$3,0,ROUND(SQRT((NodeData!$D9-NodeData!$D14)^2+(NodeData!$E9-NodeData!$E14)^2)/UAV_Params!$B$8+ABS(NodeData!$F9-NodeData!$F14)/UAV_Params!$B$9,1)) -> 19.1 | N9: =IF($A9=N$3,0,ROUND(SQRT((NodeData!$D9-NodeData!$D15)^2+(NodeData!$E9-NodeData!$E15)^2)/UAV_Params!$B$8+ABS(NodeData!$F9-NodeData!$F15)/UAV_Params!$B$9,1)) -> 29.7 | O9: =IF($A9=O$3,0,ROUND(SQRT((NodeData!$D9-NodeData!$D16)^2+(NodeData!$E9-NodeData!$E16)^2)/UAV_Params!$B$8+ABS(NodeData!$F9-NodeData!$F16)/UAV_Params!$B$9,1)) -> 31.7 | P9: =IF($A9=P$3,0,ROUND(SQRT((NodeData!$D9-NodeData!$D17)^2+(NodeData!$E9-NodeData!$E17)^2)/UAV_Params!$B$8+ABS(NodeData!$F9-NodeData!$F17)/UAV_Params!$B$9,1)) -> 27.2 | Q9: =IF($A9=Q$3,0,ROUND(SQRT((NodeData!$D9-NodeData!$D18)^2+(NodeData!$E9-NodeData!$E18)^2)/UAV_Params!$B$8+ABS(NodeData!$F9-NodeData!$F18)/UAV_Params!$B$9,1)) -> 29.7 | R9: =IF($A9=R$3,0,ROUND(SQRT((NodeData!$D9-NodeData!$D19)^2+(NodeData!$E9-NodeData!$E19)^2)/UAV_Params!$B$8+ABS(NodeData!$F9-NodeData!$F19)/UAV_Params!$B$9,1)) -> 32.9 | S9: =IF($A9=S$3,0,ROUND(SQRT((NodeData!$D9-NodeData!$D20)^2+(NodeData!$E9-NodeData!$E20)^2)/UAV_Params!$B$8+ABS(NodeData!$F9-NodeData!$F20)/UAV_Params!$B$9,1)) -> 29.2
A10: 6 | B10: B2-北立面瓷砖鼓包 | C10: =IF($A10=C$3,0,ROUND(SQRT((NodeData!$D10-NodeData!$D4)^2+(NodeData!$E10-NodeData!$E4)^2)/UAV_Params!$B$8+ABS(NodeData!$F10-NodeData!$F4)/UAV_Params!$B$9,1)) -> 19 | D10: =IF($A10=D$3,0,ROUND(SQRT((NodeData!$D10-NodeData!$D5)^2+(NodeData!$E10-NodeData!$E5)^2)/UAV_Params!$B$8+ABS(NodeData!$F10-NodeData!$F5)/UAV_Params!$B$9,1)) -> 10.8 | E10: =IF($A10=E$3,0,ROUND(SQRT((NodeData!$D10-NodeData!$D6)^2+(NodeData!$E10-NodeData!$E6)^2)/UAV_Params!$B$8+ABS(NodeData!$F10-NodeData!$F6)/UAV_Params!$B$9,1)) -> 14.3 | F10: =IF($A10=F$3,0,ROUND(SQRT((NodeData!$D10-NodeData!$D7)^2+(NodeData!$E10-NodeData!$E7)^2)/UAV_Params!$B$8+ABS(NodeData!$F10-NodeData!$F7)/UAV_Params!$B$9,1)) -> 11.5 | G10: =IF($A10=G$3,0,ROUND(SQRT((NodeData!$D10-NodeData!$D8)^2+(NodeData!$E10-NodeData!$E8)^2)/UAV_Params!$B$8+ABS(NodeData!$F10-NodeData!$F8)/UAV_Params!$B$9,1)) -> 2.6 | H10: =IF($A10=H$3,0,ROUND(SQRT((NodeData!$D10-NodeData!$D9)^2+(NodeData!$E10-NodeData!$E9)^2)/UAV_Params!$B$8+ABS(NodeData!$F10-NodeData!$F9)/UAV_Params!$B$9,1)) -> 7.7 | I10: =IF($A10=I$3,0,ROUND(SQRT((NodeData!$D10-NodeData!$D10)^2+(NodeData!$E10-NodeData!$E10)^2)/UAV_Params!$B$8+ABS(NodeData!$F10-NodeData!$F10)/UAV_Params!$B$9,1)) -> 0 | J10: =IF($A10=J$3,0,ROUND(SQRT((NodeData!$D10-NodeData!$D11)^2+(NodeData!$E10-NodeData!$E11)^2)/UAV_Params!$B$8+ABS(NodeData!$F10-NodeData!$F11)/UAV_Params!$B$9,1)) -> 9.5 | K10: =IF($A10=K$3,0,ROUND(SQRT((NodeData!$D10-NodeData!$D12)^2+(NodeData!$E10-NodeData!$E12)^2)/UAV_Params!$B$8+ABS(NodeData!$F10-NodeData!$F12)/UAV_Params!$B$9,1)) -> 11.6 | L10: =IF($A10=L$3,0,ROUND(SQRT((NodeData!$D10-NodeData!$D13)^2+(NodeData!$E10-NodeData!$E13)^2)/UAV_Params!$B$8+ABS(NodeData!$F10-NodeData!$F13)/UAV_Params!$B$9,1)) -> 18.7 | M10: =IF($A10=M$3,0,ROUND(SQRT((NodeData!$D10-NodeData!$D14)^2+(NodeData!$E10-NodeData!$E14)^2)/UAV_Params!$B$8+ABS(NodeData!$F10-NodeData!$F14)/UAV_Params!$B$9,1)) -> 20.7 | N10: =IF($A10=N$3,0,ROUND(SQRT((NodeData!$D10-NodeData!$D15)^2+(NodeData!$E10-NodeData!$E15)^2)/UAV_Params!$B$8+ABS(NodeData!$F10-NodeData!$F15)/UAV_Params!$B$9,1)) -> 29.7 | O10: =IF($A10=O$3,0,ROUND(SQRT((NodeData!$D10-NodeData!$D16)^2+(NodeData!$E10-NodeData!$E16)^2)/UAV_Params!$B$8+ABS(NodeData!$F10-NodeData!$F16)/UAV_Params!$B$9,1)) -> 27.2 | P10: =IF($A10=P$3,0,ROUND(SQRT((NodeData!$D10-NodeData!$D17)^2+(NodeData!$E10-NodeData!$E17)^2)/UAV_Params!$B$8+ABS(NodeData!$F10-NodeData!$F17)/UAV_Params!$B$9,1)) -> 28.7 | Q10: =IF($A10=Q$3,0,ROUND(SQRT((NodeData!$D10-NodeData!$D18)^2+(NodeData!$E10-NodeData!$E18)^2)/UAV_Params!$B$8+ABS(NodeData!$F10-NodeData!$F18)/UAV_Params!$B$9,1)) -> 28.3 | R10: =IF($A10=R$3,0,ROUND(SQRT((NodeData!$D10-NodeData!$D19)^2+(NodeData!$E10-NodeData!$E19)^2)/UAV_Params!$B$8+ABS(NodeData!$F10-NodeData!$F19)/UAV_Params!$B$9,1)) -> 34.1 | S10: =IF($A10=S$3,0,ROUND(SQRT((NodeData!$D10-NodeData!$D20)^2+(NodeData!$E10-NodeData!$E20)^2)/UAV_Params!$B$8+ABS(NodeData!$F10-NodeData!$F20)/UAV_Params!$B$9,1)) -> 36.5
A11: 7 | B11: B3-西侧窗框松动 | C11: =IF($A11=C$3,0,ROUND(SQRT((NodeData!$D11-NodeData!$D4)^2+(NodeData!$E11-NodeData!$E4)^2)/UAV_Params!$B$8+ABS(NodeData!$F11-NodeData!$F4)/UAV_Params!$B$9,1)) -> 22.9 | D11: =IF($A11=D$3,0,ROUND(SQRT((NodeData!$D11-NodeData!$D5)^2+(NodeData!$E11-NodeData!$E5)^2)/UAV_Params!$B$8+ABS(NodeData!$F11-NodeData!$F5)/UAV_Params!$B$9,1)) -> 19 | E11: =IF($A11=E$3,0,ROUND(SQRT((NodeData!$D11-NodeData!$D6)^2+(NodeData!$E11-NodeData!$E6)^2)/UAV_Params!$B$8+ABS(NodeData!$F11-NodeData!$F6)/UAV_Params!$B$9,1)) -> 20.3 | F11: =IF($A11=F$3,0,ROUND(SQRT((NodeData!$D11-NodeData!$D7)^2+(NodeData!$E11-NodeData!$E7)^2)/UAV_Params!$B$8+ABS(NodeData!$F11-NodeData!$F7)/UAV_Params!$B$9,1)) -> 17.4 | G11: =IF($A11=G$3,0,ROUND(SQRT((NodeData!$D11-NodeData!$D8)^2+(NodeData!$E11-NodeData!$E8)^2)/UAV_Params!$B$8+ABS(NodeData!$F11-NodeData!$F8)/UAV_Params!$B$9,1)) -> 10 | H11: =IF($A11=H$3,0,ROUND(SQRT((NodeData!$D11-NodeData!$D9)^2+(NodeData!$E11-NodeData!$E9)^2)/UAV_Params!$B$8+ABS(NodeData!$F11-NodeData!$F9)/UAV_Params!$B$9,1)) -> 14 | I11: =IF($A11=I$3,0,ROUND(SQRT((NodeData!$D11-NodeData!$D10)^2+(NodeData!$E11-NodeData!$E10)^2)/UAV_Params!$B$8+ABS(NodeData!$F11-NodeData!$F10)/UAV_Params!$B$9,1)) -> 9.5 | J11: =IF($A11=J$3,0,ROUND(SQRT((NodeData!$D11-NodeData!$D11)^2+(NodeData!$E11-NodeData!$E11)^2)/UAV_Params!$B$8+ABS(NodeData!$F11-NodeData!$F11)/UAV_Params!$B$9,1)) -> 0 | K11: =IF($A11=K$3,0,ROUND(SQRT((NodeData!$D11-NodeData!$D12)^2+(NodeData!$E11-NodeData!$E12)^2)/UAV_Params!$B$8+ABS(NodeData!$F11-NodeData!$F12)/UAV_Params!$B$9,1)) -> 5 | L11: =IF($A11=L$3,0,ROUND(SQRT((NodeData!$D11-NodeData!$D13)^2+(NodeData!$E11-NodeData!$E13)^2)/UAV_Params!$B$8+ABS(NodeData!$F11-NodeData!$F13)/UAV_Params!$B$9,1)) -> 16.6 | M11: =IF($A11=M$3,0,ROUND(SQRT((NodeData!$D11-NodeData!$D14)^2+(NodeData!$E11-NodeData!$E14)^2)/UAV_Params!$B$8+ABS(NodeData!$F11-NodeData!$F14)/UAV_Params!$B$9,1)) -> 16.2 | N11: =IF($A11=N$3,0,ROUND(SQRT((NodeData!$D11-NodeData!$D15)^2+(NodeData!$E11-NodeData!$E15)^2)/UAV_Params!$B$8+ABS(NodeData!$F11-NodeData!$F15)/UAV_Params!$B$9,1)) -> 26.8 | O11: =IF($A11=O$3,0,ROUND(SQRT((NodeData!$D11-NodeData!$D16)^2+(NodeData!$E11-NodeData!$E16)^2)/UAV_Params!$B$8+ABS(NodeData!$F11-NodeData!$F16)/UAV_Params!$B$9,1)) -> 27.4 | P11: =IF($A11=P$3,0,ROUND(SQRT((NodeData!$D11-NodeData!$D17)^2+(NodeData!$E11-NodeData!$E17)^2)/UAV_Params!$B$8+ABS(NodeData!$F11-NodeData!$F17)/UAV_Params!$B$9,1)) -> 30.8 | Q11: =IF($A11=Q$3,0,ROUND(SQRT((NodeData!$D11-NodeData!$D18)^2+(NodeData!$E11-NodeData!$E18)^2)/UAV_Params!$B$8+ABS(NodeData!$F11-NodeData!$F18)/UAV_Params!$B$9,1)) -> 32.7 | R11: =IF($A11=R$3,0,ROUND(SQRT((NodeData!$D11-NodeData!$D19)^2+(NodeData!$E11-NodeData!$E19)^2)/UAV_Params!$B$8+ABS(NodeData!$F11-NodeData!$F19)/UAV_Params!$B$9,1)) -> 37.9 | S11: =IF($A11=S$3,0,ROUND(SQRT((NodeData!$D11-NodeData!$D20)^2+(NodeData!$E11-NodeData!$E20)^2)/UAV_Params!$B$8+ABS(NodeData!$F11-NodeData!$F20)/UAV_Params!$B$9,1)) -> 40.6
A12: 8 | B12: B3-屋顶通信箱体 | C12: =IF($A12=C$3,0,ROUND(SQRT((NodeData!$D12-NodeData!$D4)^2+(NodeData!$E12-NodeData!$E4)^2)/UAV_Params!$B$8+ABS(NodeData!$F12-NodeData!$F4)/UAV_Params!$B$9,1)) -> 25.3 | D12: =IF($A12=D$3,0,ROUND(SQRT((NodeData!$D12-NodeData!$D5)^2+(NodeData!$E12-NodeData!$E5)^2)/UAV_Params!$B$8+ABS(NodeData!$F12-NodeData!$F5)/UAV_Params!$B$9,1)) -> 21 | E12: =IF($A12=E$3,0,ROUND(SQRT((NodeData!$D12-NodeData!$D6)^2+(NodeData!$E12-NodeData!$E6)^2)/UAV_Params!$B$8+ABS(NodeData!$F12-NodeData!$F6)/UAV_Params!$B$9,1)) -> 17.7 | F12: =IF($A12=F$3,0,ROUND(SQRT((NodeData!$D12-NodeData!$D7)^2+(NodeData!$E12-NodeData!$E7)^2)/UAV_Params!$B$8+ABS(NodeData!$F12-NodeData!$F7)/UAV_Params!$B$9,1)) -> 18.4 | G12: =IF($A12=G$3,0,ROUND(SQRT((NodeData!$D12-NodeData!$D8)^2+(NodeData!$E12-NodeData!$E8)^2)/UAV_Params!$B$8+ABS(NodeData!$F12-NodeData!$F8)/UAV_Params!$B$9,1)) -> 12.1 | H12: =IF($A12=H$3,0,ROUND(SQRT((NodeData!$D12-NodeData!$D9)^2+(NodeData!$E12-NodeData!$E9)^2)/UAV_Params!$B$8+ABS(NodeData!$F12-NodeData!$F9)/UAV_Params!$B$9,1)) -> 10 | I12: =IF($A12=I$3,0,ROUND(SQRT((NodeData!$D12-NodeData!$D10)^2+(NodeData!$E12-NodeData!$E10)^2)/UAV_Params!$B$8+ABS(NodeData!$F12-NodeData!$F10)/UAV_Params!$B$9,1)) -> 11.6 | J12: =IF($A12=J$3,0,ROUND(SQRT((NodeData!$D12-NodeData!$D11)^2+(NodeData!$E12-NodeData!$E11)^2)/UAV_Params!$B$8+ABS(NodeData!$F12-NodeData!$F11)/UAV_Params!$B$9,1)) -> 5 | K12: =IF($A12=K$3,0,ROUND(SQRT((NodeData!$D12-NodeData!$D12)^2+(NodeData!$E12-NodeData!$E12)^2)/UAV_Params!$B$8+ABS(NodeData!$F12-NodeData!$F12)/UAV_Params!$B$9,1)) -> 0 | L12: =IF($A12=L$3,0,ROUND(SQRT((NodeData!$D12-NodeData!$D13)^2+(NodeData!$E12-NodeData!$E13)^2)/UAV_Params!$B$8+ABS(NodeData!$F12-NodeData!$F13)/UAV_Params!$B$9,1)) -> 19.9 | M12: =IF($A12=M$3,0,ROUND(SQRT((NodeData!$D12-NodeData!$D14)^2+(NodeData!$E12-NodeData!$E14)^2)/UAV_Params!$B$8+ABS(NodeData!$F12-NodeData!$F14)/UAV_Params!$B$9,1)) -> 15.4 | N12: =IF($A12=N$3,0,ROUND(SQRT((NodeData!$D12-NodeData!$D15)^2+(NodeData!$E12-NodeData!$E15)^2)/UAV_Params!$B$8+ABS(NodeData!$F12-NodeData!$F15)/UAV_Params!$B$9,1)) -> 28.4 | O12: =IF($A12=O$3,0,ROUND(SQRT((NodeData!$D12-NodeData!$D16)^2+(NodeData!$E12-NodeData!$E16)^2)/UAV_Params!$B$8+ABS(NodeData!$F12-NodeData!$F16)/UAV_Params!$B$9,1)) -> 30.4 | P12: =IF($A12=P$3,0,ROUND(SQRT((NodeData!$D12-NodeData!$D17)^2+(NodeData!$E12-NodeData!$E17)^2)/UAV_Params!$B$8+ABS(NodeData!$F12-NodeData!$F17)/UAV_Params!$B$9,1)) -> 32.1 | Q12: =IF($A12=Q$3,0,ROUND(SQRT((NodeData!$D12-NodeData!$D18)^2+(NodeData!$E12-NodeData!$E18)^2)/UAV_Params!$B$8+ABS(NodeData!$F12-NodeData!$F18)/UAV_Params!$B$9,1)) -> 34.9 | R12: =IF($A12=R$3,0,ROUND(SQRT((NodeData!$D12-NodeData!$D19)^2+(NodeData!$E12-NodeData!$E19)^2)/UAV_Params!$B$8+ABS(NodeData!$F12-NodeData!$F19)/UAV_Params!$B$9,1)) -> 40 | S12: =IF($A12=S$3,0,ROUND(SQRT((NodeData!$D12-NodeData!$D20)^2+(NodeData!$E12-NodeData!$E20)^2)/UAV_Params!$B$8+ABS(NodeData!$F12-NodeData!$F20)/UAV_Params!$B$9,1)) -> 36.7
A13: 9 | B13: B4-南外墙脱落点 | C13: =IF($A13=C$3,0,ROUND(SQRT((NodeData!$D13-NodeData!$D4)^2+(NodeData!$E13-NodeData!$E4)^2)/UAV_Params!$B$8+ABS(NodeData!$F13-NodeData!$F4)/UAV_Params!$B$9,1)) -> 15.6 | D13: =IF($A13=D$3,0,ROUND(SQRT((NodeData!$D13-NodeData!$D5)^2+(NodeData!$E13-NodeData!$E5)^2)/UAV_Params!$B$8+ABS(NodeData!$F13-NodeData!$F5)/UAV_Params!$B$9,1)) -> 23.6 | E13: =IF($A13=E$3,0,ROUND(SQRT((NodeData!$D13-NodeData!$D6)^2+(NodeData!$E13-NodeData!$E6)^2)/UAV_Params!$B$8+ABS(NodeData!$F13-NodeData!$F6)/UAV_Params!$B$9,1)) -> 25.8 | F13: =IF($A13=F$3,0,ROUND(SQRT((NodeData!$D13-NodeData!$D7)^2+(NodeData!$E13-NodeData!$E7)^2)/UAV_Params!$B$8+ABS(NodeData!$F13-NodeData!$F7)/UAV_Params!$B$9,1)) -> 23.2 | G13: =IF($A13=G$3,0,ROUND(SQRT((NodeData!$D13-NodeData!$D8)^2+(NodeData!$E13-NodeData!$E8)^2)/UAV_Params!$B$8+ABS(NodeData!$F13-NodeData!$F8)/UAV_Params!$B$9,1)) -> 19.6 | H13: =IF($A13=H$3,0,ROUND(SQRT((NodeData!$D13-NodeData!$D9)^2+(NodeData!$E13-NodeData!$E9)^2)/UAV_Params!$B$8+ABS(NodeData!$F13-NodeData!$F9)/UAV_Params!$B$9,1)) -> 23.6 | I13: =IF($A13=I$3,0,ROUND(SQRT((NodeData!$D13-NodeData!$D10)^2+(NodeData!$E13-NodeData!$E10)^2)/UAV_Params!$B$8+ABS(NodeData!$F13-NodeData!$F10)/UAV_Params!$B$9,1)) -> 18.7 | J13: =IF($A13=J$3,0,ROUND(SQRT((NodeData!$D13-NodeData!$D11)^2+(NodeData!$E13-NodeData!$E11)^2)/UAV_Params!$B$8+ABS(NodeData!$F13-NodeData!$F11)/UAV_Params!$B$9,1)) -> 16.6 | K13: =IF($A13=K$3,0,ROUND(SQRT((NodeData!$D13-NodeData!$D12)^2+(NodeData!$E13-NodeData!$E12)^2)/UAV_Params!$B$8+ABS(NodeData!$F13-NodeData!$F12)/UAV_Params!$B$9,1)) -> 19.9 | L13: =IF($A13=L$3,0,ROUND(SQRT((NodeData!$D13-NodeData!$D13)^2+(NodeData!$E13-NodeData!$E13)^2)/UAV_Params!$B$8+ABS(NodeData!$F13-NodeData!$F13)/UAV_Params!$B$9,1)) -> 0 | M13: =IF($A13=M$3,0,ROUND(SQRT((NodeData!$D13-NodeData!$D14)^2+(NodeData!$E13-NodeData!$E14)^2)/UAV_Params!$B$8+ABS(NodeData!$F13-NodeData!$F14)/UAV_Params!$B$9,1)) -> 4.6 | N13: =IF($A13=N$3,0,ROUND(SQRT((NodeData!$D13-NodeData!$D15)^2+(NodeData!$E13-NodeData!$E15)^2)/UAV_Params!$B$8+ABS(NodeData!$F13-NodeData!$F15)/UAV_Params!$B$9,1)) -> 13 | O13: =IF($A13=O$3,0,ROUND(SQRT((NodeData!$D13-NodeData!$D16)^2+(NodeData!$E13-NodeData!$E16)^2)/UAV_Params!$B$8+ABS(NodeData!$F13-NodeData!$F16)/UAV_Params!$B$9,1)) -> 11.2 | P13: =IF($A13=P$3,0,ROUND(SQRT((NodeData!$D13-NodeData!$D17)^2+(NodeData!$E13-NodeData!$E17)^2)/UAV_Params!$B$8+ABS(NodeData!$F13-NodeData!$F17)/UAV_Params!$B$9,1)) -> 23.5 | Q13: =IF($A13=Q$3,0,ROUND(SQRT((NodeData!$D13-NodeData!$D18)^2+(NodeData!$E13-NodeData!$E18)^2)/UAV_Params!$B$8+ABS(NodeData!$F13-NodeData!$F18)/UAV_Params!$B$9,1)) -> 23.5 | R13: =IF($A13=R$3,0,ROUND(SQRT((NodeData!$D13-NodeData!$D19)^2+(NodeData!$E13-NodeData!$E19)^2)/UAV_Params!$B$8+ABS(NodeData!$F13-NodeData!$F19)/UAV_Params!$B$9,1)) -> 33.2 | S13: =IF($A13=S$3,0,ROUND(SQRT((NodeData!$D13-NodeData!$D20)^2+(NodeData!$E13-NodeData!$E20)^2)/UAV_Params!$B$8+ABS(NodeData!$F13-NodeData!$F20)/UAV_Params!$B$9,1)) -> 36.4
A14: 10 | B14: B4-屋顶天沟堆积 | C14: =IF($A14=C$3,0,ROUND(SQRT((NodeData!$D14-NodeData!$D4)^2+(NodeData!$E14-NodeData!$E4)^2)/UAV_Params!$B$8+ABS(NodeData!$F14-NodeData!$F4)/UAV_Params!$B$9,1)) -> 18.2 | D14: =IF($A14=D$3,0,ROUND(SQRT((NodeData!$D14-NodeData!$D5)^2+(NodeData!$E14-NodeData!$E5)^2)/UAV_Params!$B$8+ABS(NodeData!$F14-NodeData!$F5)/UAV_Params!$B$9,1)) -> 25.2 | E14: =IF($A14=E$3,0,ROUND(SQRT((NodeData!$D14-NodeData!$D6)^2+(NodeData!$E14-NodeData!$E6)^2)/UAV_Params!$B$8+ABS(NodeData!$F14-NodeData!$F6)/UAV_Params!$B$9,1)) -> 21.5 | F14: =IF($A14=F$3,0,ROUND(SQRT((NodeData!$D14-NodeData!$D7)^2+(NodeData!$E14-NodeData!$E7)^2)/UAV_Params!$B$8+ABS(NodeData!$F14-NodeData!$F7)/UAV_Params!$B$9,1)) -> 21.8 | G14: =IF($A14=G$3,0,ROUND(SQRT((NodeData!$D14-NodeData!$D8)^2+(NodeData!$E14-NodeData!$E8)^2)/UAV_Params!$B$8+ABS(NodeData!$F14-NodeData!$F8)/UAV_Params!$B$9,1)) -> 20 | H14: =IF($A14=H$3,0,ROUND(SQRT((NodeData!$D14-NodeData!$D9)^2+(NodeData!$E14-NodeData!$E9)^2)/UAV_Params!$B$8+ABS(NodeData!$F14-NodeData!$F9)/UAV_Params!$B$9,1)) -> 19.1 | I14: =IF($A14=I$3,0,ROUND(SQRT((NodeData!$D14-NodeData!$D10)^2+(NodeData!$E14-NodeData!$E10)^2)/UAV_Params!$B$8+ABS(NodeData!$F14-NodeData!$F10)/UAV_Params!$B$9,1)) -> 20.7 | J14: =IF($A14=J$3,0,ROUND(SQRT((NodeData!$D14-NodeData!$D11)^2+(NodeData!$E14-NodeData!$E11)^2)/UAV_Params!$B$8+ABS(NodeData!$F14-NodeData!$F11)/UAV_Params!$B$9,1)) -> 16.2 | K14: =IF($A14=K$3,0,ROUND(SQRT((NodeData!$D14-NodeData!$D12)^2+(NodeData!$E14-NodeData!$E12)^2)/UAV_Params!$B$8+ABS(NodeData!$F14-NodeData!$F12)/UAV_Params!$B$9,1)) -> 15.4 | L14: =IF($A14=L$3,0,ROUND(SQRT((NodeData!$D14-NodeData!$D13)^2+(NodeData!$E14-NodeData!$E13)^2)/UAV_Params!$B$8+ABS(NodeData!$F14-NodeData!$F13)/UAV_Params!$B$9,1)) -> 4.6 | M14: =IF($A14=M$3,0,ROUND(SQRT((NodeData!$D14-NodeData!$D14)^2+(NodeData!$E14-NodeData!$E14)^2)/UAV_Params!$B$8+ABS(NodeData!$F14-NodeData!$F14)/UAV_Params!$B$9,1)) -> 0 | N14: =IF($A14=N$3,0,ROUND(SQRT((NodeData!$D14-NodeData!$D15)^2+(NodeData!$E14-NodeData!$E15)^2)/UAV_Params!$B$8+ABS(NodeData!$F14-NodeData!$F15)/UAV_Params!$B$9,1)) -> 13.3 | O14: =IF($A14=O$3,0,ROUND(SQRT((NodeData!$D14-NodeData!$D16)^2+(NodeData!$E14-NodeData!$E16)^2)/UAV_Params!$B$8+ABS(NodeData!$F14-NodeData!$F16)/UAV_Params!$B$9,1)) -> 15.4 | P14: =IF($A14=P$3,0,ROUND(SQRT((NodeData!$D14-NodeData!$D17)^2+(NodeData!$E14-NodeData!$E17)^2)/UAV_Params!$B$8+ABS(NodeData!$F14-NodeData!$F17)/UAV_Params!$B$9,1)) -> 23.2 | Q14: =IF($A14=Q$3,0,ROUND(SQRT((NodeData!$D14-NodeData!$D18)^2+(NodeData!$E14-NodeData!$E18)^2)/UAV_Params!$B$8+ABS(NodeData!$F14-NodeData!$F18)/UAV_Params!$B$9,1)) -> 26.2 | R14: =IF($A14=R$3,0,ROUND(SQRT((NodeData!$D14-NodeData!$D19)^2+(NodeData!$E14-NodeData!$E19)^2)/UAV_Params!$B$8+ABS(NodeData!$F14-NodeData!$F19)/UAV_Params!$B$9,1)) -> 33.7 | S14: =IF($A14=S$3,0,ROUND(SQRT((NodeData!$D14-NodeData!$D20)^2+(NodeData!$E14-NodeData!$E20)^2)/UAV_Params!$B$8+ABS(NodeData!$F14-NodeData!$F20)/UAV_Params!$B$9,1)) -> 32.9
A15: 11 | B15: B5-屋顶消防标识遮挡 | C15: =IF($A15=C$3,0,ROUND(SQRT((NodeData!$D15-NodeData!$D4)^2+(NodeData!$E15-NodeData!$E4)^2)/UAV_Params!$B$8+ABS(NodeData!$F15-NodeData!$F4)/UAV_Params!$B$9,1)) -> 20.9 | D15: =IF($A15=D$3,0,ROUND(SQRT((NodeData!$D15-NodeData!$D5)^2+(NodeData!$E15-NodeData!$E5)^2)/UAV_Params!$B$8+ABS(NodeData!$F15-NodeData!$F5)/UAV_Params!$B$9,1)) -> 30.9 | E15: =IF($A15=E$3,0,ROUND(SQRT((NodeData!$D15-NodeData!$D6)^2+(NodeData!$E15-NodeData!$E6)^2)/UAV_Params!$B$8+ABS(NodeData!$F15-NodeData!$F6)/UAV_Params!$B$9,1)) -> 29.3 | F15: =IF($A15=F$3,0,ROUND(SQRT((NodeData!$D15-NodeData!$D7)^2+(NodeData!$E15-NodeData!$E7)^2)/UAV_Params!$B$8+ABS(NodeData!$F15-NodeData!$F7)/UAV_Params!$B$9,1)) -> 27.5 | G15: =IF($A15=G$3,0,ROUND(SQRT((NodeData!$D15-NodeData!$D8)^2+(NodeData!$E15-NodeData!$E8)^2)/UAV_Params!$B$8+ABS(NodeData!$F15-NodeData!$F8)/UAV_Params!$B$9,1)) -> 28.6 | H15: =IF($A15=H$3,0,ROUND(SQRT((NodeData!$D15-NodeData!$D9)^2+(NodeData!$E15-NodeData!$E9)^2)/UAV_Params!$B$8+ABS(NodeData!$F15-NodeData!$F9)/UAV_Params!$B$9,1)) -> 29.7 | I15: =IF($A15=I$3,0,ROUND(SQRT((NodeData!$D15-NodeData!$D10)^2+(NodeData!$E15-NodeData!$E10)^2)/UAV_Params!$B$8+ABS(NodeData!$F15-NodeData!$F10)/UAV_Params!$B$9,1)) -> 29.7 | J15: =IF($A15=J$3,0,ROUND(SQRT((NodeData!$D15-NodeData!$D11)^2+(NodeData!$E15-NodeData!$E11)^2)/UAV_Params!$B$8+ABS(NodeData!$F15-NodeData!$F11)/UAV_Params!$B$9,1)) -> 26.8 | K15: =IF($A15=K$3,0,ROUND(SQRT((NodeData!$D15-NodeData!$D12)^2+(NodeData!$E15-NodeData!$E12)^2)/UAV_Params!$B$8+ABS(NodeData!$F15-NodeData!$F12)/UAV_Params!$B$9,1)) -> 28.4 | L15: =IF($A15=L$3,0,ROUND(SQRT((NodeData!$D15-NodeData!$D13)^2+(NodeData!$E15-NodeData!$E13)^2)/UAV_Params!$B$8+ABS(NodeData!$F15-NodeData!$F13)/UAV_Params!$B$9,1)) -> 13 | M15: =IF($A15=M$3,0,ROUND(SQRT((NodeData!$D15-NodeData!$D14)^2+(NodeData!$E15-NodeData!$E14)^2)/UAV_Params!$B$8+ABS(NodeData!$F15-NodeData!$F14)/UAV_Params!$B$9,1)) -> 13.3 | N15: =IF($A15=N$3,0,ROUND(SQRT((NodeData!$D15-NodeData!$D15)^2+(NodeData!$E15-NodeData!$E15)^2)/UAV_Params!$B$8+ABS(NodeData!$F15-NodeData!$F15)/UAV_Params!$B$9,1)) -> 0 | O15: =IF($A15=O$3,0,ROUND(SQRT((NodeData!$D15-NodeData!$D16)^2+(NodeData!$E15-NodeData!$E16)^2)/UAV_Params!$B$8+ABS(NodeData!$F15-NodeData!$F16)/UAV_Params!$B$9,1)) -> 4.6 | P15: =IF($A15=P$3,0,ROUND(SQRT((NodeData!$D15-NodeData!$D17)^2+(NodeData!$E15-NodeData!$E17)^2)/UAV_Params!$B$8+ABS(NodeData!$F15-NodeData!$F17)/UAV_Params!$B$9,1)) -> 17.7 | Q15: =IF($A15=Q$3,0,ROUND(SQRT((NodeData!$D15-NodeData!$D18)^2+(NodeData!$E15-NodeData!$E18)^2)/UAV_Params!$B$8+ABS(NodeData!$F15-NodeData!$F18)/UAV_Params!$B$9,1)) -> 20.6 | R15: =IF($A15=R$3,0,ROUND(SQRT((NodeData!$D15-NodeData!$D19)^2+(NodeData!$E15-NodeData!$E19)^2)/UAV_Params!$B$8+ABS(NodeData!$F15-NodeData!$F19)/UAV_Params!$B$9,1)) -> 28.9 | S15: =IF($A15=S$3,0,ROUND(SQRT((NodeData!$D15-NodeData!$D20)^2+(NodeData!$E15-NodeData!$E20)^2)/UAV_Params!$B$8+ABS(NodeData!$F15-NodeData!$F20)/UAV_Params!$B$9,1)) -> 31.2
A16: 12 | B16: B5-东侧外挂线缆 | C16: =IF($A16=C$3,0,ROUND(SQRT((NodeData!$D16-NodeData!$D4)^2+(NodeData!$E16-NodeData!$E4)^2)/UAV_Params!$B$8+ABS(NodeData!$F16-NodeData!$F4)/UAV_Params!$B$9,1)) -> 16.4 | D16: =IF($A16=D$3,0,ROUND(SQRT((NodeData!$D16-NodeData!$D5)^2+(NodeData!$E16-NodeData!$E5)^2)/UAV_Params!$B$8+ABS(NodeData!$F16-NodeData!$F5)/UAV_Params!$B$9,1)) -> 29.4 | E16: =IF($A16=E$3,0,ROUND(SQRT((NodeData!$D16-NodeData!$D6)^2+(NodeData!$E16-NodeData!$E6)^2)/UAV_Params!$B$8+ABS(NodeData!$F16-NodeData!$F6)/UAV_Params!$B$9,1)) -> 31.4 | F16: =IF($A16=F$3,0,ROUND(SQRT((NodeData!$D16-NodeData!$D7)^2+(NodeData!$E16-NodeData!$E7)^2)/UAV_Params!$B$8+ABS(NodeData!$F16-NodeData!$F7)/UAV_Params!$B$9,1)) -> 29 | G16: =IF($A16=G$3,0,ROUND(SQRT((NodeData!$D16-NodeData!$D8)^2+(NodeData!$E16-NodeData!$E8)^2)/UAV_Params!$B$8+ABS(NodeData!$F16-NodeData!$F8)/UAV_Params!$B$9,1)) -> 28.1 | H16: =IF($A16=H$3,0,ROUND(SQRT((NodeData!$D16-NodeData!$D9)^2+(NodeData!$E16-NodeData!$E9)^2)/UAV_Params!$B$8+ABS(NodeData!$F16-NodeData!$F9)/UAV_Params!$B$9,1)) -> 31.7 | I16: =IF($A16=I$3,0,ROUND(SQRT((NodeData!$D16-NodeData!$D10)^2+(NodeData!$E16-NodeData!$E10)^2)/UAV_Params!$B$8+ABS(NodeData!$F16-NodeData!$F10)/UAV_Params!$B$9,1)) -> 27.2 | J16: =IF($A16=J$3,0,ROUND(SQRT((NodeData!$D16-NodeData!$D11)^2+(NodeData!$E16-NodeData!$E11)^2)/UAV_Params!$B$8+ABS(NodeData!$F16-NodeData!$F11)/UAV_Params!$B$9,1)) -> 27.4 | K16: =IF($A16=K$3,0,ROUND(SQRT((NodeData!$D16-NodeData!$D12)^2+(NodeData!$E16-NodeData!$E12)^2)/UAV_Params!$B$8+ABS(NodeData!$F16-NodeData!$F12)/UAV_Params!$B$9,1)) -> 30.4 | L16: =IF($A16=L$3,0,ROUND(SQRT((NodeData!$D16-NodeData!$D13)^2+(NodeData!$E16-NodeData!$E13)^2)/UAV_Params!$B$8+ABS(NodeData!$F16-NodeData!$F13)/UAV_Params!$B$9,1)) -> 11.2 | M16: =IF($A16=M$3,0,ROUND(SQRT((NodeData!$D16-NodeData!$D14)^2+(NodeData!$E16-NodeData!$E14)^2)/UAV_Params!$B$8+ABS(NodeData!$F16-NodeData!$F14)/UAV_Params!$B$9,1)) -> 15.4 | N16: =IF($A16=N$3,0,ROUND(SQRT((NodeData!$D16-NodeData!$D15)^2+(NodeData!$E16-NodeData!$E15)^2)/UAV_Params!$B$8+ABS(NodeData!$F16-NodeData!$F15)/UAV_Params!$B$9,1)) -> 4.6 | O16: =IF($A16=O$3,0,ROUND(SQRT((NodeData!$D16-NodeData!$D16)^2+(NodeData!$E16-NodeData!$E16)^2)/UAV_Params!$B$8+ABS(NodeData!$F16-NodeData!$F16)/UAV_Params!$B$9,1)) -> 0 | P16: =IF($A16=P$3,0,ROUND(SQRT((NodeData!$D16-NodeData!$D17)^2+(NodeData!$E16-NodeData!$E17)^2)/UAV_Params!$B$8+ABS(NodeData!$F16-NodeData!$F17)/UAV_Params!$B$9,1)) -> 20.1 | Q16: =IF($A16=Q$3,0,ROUND(SQRT((NodeData!$D16-NodeData!$D18)^2+(NodeData!$E16-NodeData!$E18)^2)/UAV_Params!$B$8+ABS(NodeData!$F16-NodeData!$F18)/UAV_Params!$B$9,1)) -> 19.9 | R16: =IF($A16=R$3,0,ROUND(SQRT((NodeData!$D16-NodeData!$D19)^2+(NodeData!$E16-NodeData!$E19)^2)/UAV_Params!$B$8+ABS(NodeData!$F16-NodeData!$F19)/UAV_Params!$B$9,1)) -> 30.3 | S16: =IF($A16=S$3,0,ROUND(SQRT((NodeData!$D16-NodeData!$D20)^2+(NodeData!$E16-NodeData!$E20)^2)/UAV_Params!$B$8+ABS(NodeData!$F16-NodeData!$F20)/UAV_Params!$B$9,1)) -> 34
A17: 13 | B17: B6-屋顶空调机组异常 | C17: =IF($A17=C$3,0,ROUND(SQRT((NodeData!$D17-NodeData!$D4)^2+(NodeData!$E17-NodeData!$E4)^2)/UAV_Params!$B$8+ABS(NodeData!$F17-NodeData!$F4)/UAV_Params!$B$9,1)) -> 18.9 | D17: =IF($A17=D$3,0,ROUND(SQRT((NodeData!$D17-NodeData!$D5)^2+(NodeData!$E17-NodeData!$E5)^2)/UAV_Params!$B$8+ABS(NodeData!$F17-NodeData!$F5)/UAV_Params!$B$9,1)) -> 23.2 | E17: =IF($A17=E$3,0,ROUND(SQRT((NodeData!$D17-NodeData!$D6)^2+(NodeData!$E17-NodeData!$E6)^2)/UAV_Params!$B$8+ABS(NodeData!$F17-NodeData!$F6)/UAV_Params!$B$9,1)) -> 22.1 | F17: =IF($A17=F$3,0,ROUND(SQRT((NodeData!$D17-NodeData!$D7)^2+(NodeData!$E17-NodeData!$E7)^2)/UAV_Params!$B$8+ABS(NodeData!$F17-NodeData!$F7)/UAV_Params!$B$9,1)) -> 20.5 | G17: =IF($A17=G$3,0,ROUND(SQRT((NodeData!$D17-NodeData!$D8)^2+(NodeData!$E17-NodeData!$E8)^2)/UAV_Params!$B$8+ABS(NodeData!$F17-NodeData!$F8)/UAV_Params!$B$9,1)) -> 26.6 | H17: =IF($A17=H$3,0,ROUND(SQRT((NodeData!$D17-NodeData!$D9)^2+(NodeData!$E17-NodeData!$E9)^2)/UAV_Params!$B$8+ABS(NodeData!$F17-NodeData!$F9)/UAV_Params!$B$9,1)) -> 27.2 | I17: =IF($A17=I$3,0,ROUND(SQRT((NodeData!$D17-NodeData!$D10)^2+(NodeData!$E17-NodeData!$E10)^2)/UAV_Params!$B$8+ABS(NodeData!$F17-NodeData!$F10)/UAV_Params!$B$9,1)) -> 28.7 | J17: =IF($A17=J$3,0,ROUND(SQRT((NodeData!$D17-NodeData!$D11)^2+(NodeData!$E17-NodeData!$E11)^2)/UAV_Params!$B$8+ABS(NodeData!$F17-NodeData!$F11)/UAV_Params!$B$9,1)) -> 30.8 | K17: =IF($A17=K$3,0,ROUND(SQRT((NodeData!$D17-NodeData!$D12)^2+(NodeData!$E17-NodeData!$E12)^2)/UAV_Params!$B$8+ABS(NodeData!$F17-NodeData!$F12)/UAV_Params!$B$9,1)) -> 32.1 | L17: =IF($A17=L$3,0,ROUND(SQRT((NodeData!$D17-NodeData!$D13)^2+(NodeData!$E17-NodeData!$E13)^2)/UAV_Params!$B$8+ABS(NodeData!$F17-NodeData!$F13)/UAV_Params!$B$9,1)) -> 23.5 | M17: =IF($A17=M$3,0,ROUND(SQRT((NodeData!$D17-NodeData!$D14)^2+(NodeData!$E17-NodeData!$E14)^2)/UAV_Params!$B$8+ABS(NodeData!$F17-NodeData!$F14)/UAV_Params!$B$9,1)) -> 23.2 | N17: =IF($A17=N$3,0,ROUND(SQRT((NodeData!$D17-NodeData!$D15)^2+(NodeData!$E17-NodeData!$E15)^2)/UAV_Params!$B$8+ABS(NodeData!$F17-NodeData!$F15)/UAV_Params!$B$9,1)) -> 17.7 | O17: =IF($A17=O$3,0,ROUND(SQRT((NodeData!$D17-NodeData!$D16)^2+(NodeData!$E17-NodeData!$E16)^2)/UAV_Params!$B$8+ABS(NodeData!$F17-NodeData!$F16)/UAV_Params!$B$9,1)) -> 20.1 | P17: =IF($A17=P$3,0,ROUND(SQRT((NodeData!$D17-NodeData!$D17)^2+(NodeData!$E17-NodeData!$E17)^2)/UAV_Params!$B$8+ABS(NodeData!$F17-NodeData!$F17)/UAV_Params!$B$9,1)) -> 0 | Q17: =IF($A17=Q$3,0,ROUND(SQRT((NodeData!$D17-NodeData!$D18)^2+(NodeData!$E17-NodeData!$E18)^2)/UAV_Params!$B$8+ABS(NodeData!$F17-NodeData!$F18)/UAV_Params!$B$9,1)) -> 3 | R17: =IF($A17=R$3,0,ROUND(SQRT((NodeData!$D17-NodeData!$D19)^2+(NodeData!$E17-NodeData!$E19)^2)/UAV_Params!$B$8+ABS(NodeData!$F17-NodeData!$F19)/UAV_Params!$B$9,1)) -> 11.2 | S17: =IF($A17=S$3,0,ROUND(SQRT((NodeData!$D17-NodeData!$D20)^2+(NodeData!$E17-NodeData!$E20)^2)/UAV_Params!$B$8+ABS(NodeData!$F17-NodeData!$F20)/UAV_Params!$B$9,1)) -> 13.9
A18: 14 | B18: B6-西立面渗水痕迹 | C18: =IF($A18=C$3,0,ROUND(SQRT((NodeData!$D18-NodeData!$D4)^2+(NodeData!$E18-NodeData!$E4)^2)/UAV_Params!$B$8+ABS(NodeData!$F18-NodeData!$F4)/UAV_Params!$B$9,1)) -> 18.8 | D18: =IF($A18=D$3,0,ROUND(SQRT((NodeData!$D18-NodeData!$D5)^2+(NodeData!$E18-NodeData!$E5)^2)/UAV_Params!$B$8+ABS(NodeData!$F18-NodeData!$F5)/UAV_Params!$B$9,1)) -> 22.5 | E18: =IF($A18=E$3,0,ROUND(SQRT((NodeData!$D18-NodeData!$D6)^2+(NodeData!$E18-NodeData!$E6)^2)/UAV_Params!$B$8+ABS(NodeData!$F18-NodeData!$F6)/UAV_Params!$B$9,1)) -> 24.3 | F18: =IF($A18=F$3,0,ROUND(SQRT((NodeData!$D18-NodeData!$D7)^2+(NodeData!$E18-NodeData!$E7)^2)/UAV_Params!$B$8+ABS(NodeData!$F18-NodeData!$F7)/UAV_Params!$B$9,1)) -> 22.8 | G18: =IF($A18=G$3,0,ROUND(SQRT((NodeData!$D18-NodeData!$D8)^2+(NodeData!$E18-NodeData!$E8)^2)/UAV_Params!$B$8+ABS(NodeData!$F18-NodeData!$F8)/UAV_Params!$B$9,1)) -> 27.2 | H18: =IF($A18=H$3,0,ROUND(SQRT((NodeData!$D18-NodeData!$D9)^2+(NodeData!$E18-NodeData!$E9)^2)/UAV_Params!$B$8+ABS(NodeData!$F18-NodeData!$F9)/UAV_Params!$B$9,1)) -> 29.7 | I18: =IF($A18=I$3,0,ROUND(SQRT((NodeData!$D18-NodeData!$D10)^2+(NodeData!$E18-NodeData!$E10)^2)/UAV_Params!$B$8+ABS(NodeData!$F18-NodeData!$F10)/UAV_Params!$B$9,1)) -> 28.3 | J18: =IF($A18=J$3,0,ROUND(SQRT((NodeData!$D18-NodeData!$D11)^2+(NodeData!$E18-NodeData!$E11)^2)/UAV_Params!$B$8+ABS(NodeData!$F18-NodeData!$F11)/UAV_Params!$B$9,1)) -> 32.7 | K18: =IF($A18=K$3,0,ROUND(SQRT((NodeData!$D18-NodeData!$D12)^2+(NodeData!$E18-NodeData!$E12)^2)/UAV_Params!$B$8+ABS(NodeData!$F18-NodeData!$F12)/UAV_Params!$B$9,1)) -> 34.9 | L18: =IF($A18=L$3,0,ROUND(SQRT((NodeData!$D18-NodeData!$D13)^2+(NodeData!$E18-NodeData!$E13)^2)/UAV_Params!$B$8+ABS(NodeData!$F18-NodeData!$F13)/UAV_Params!$B$9,1)) -> 23.5 | M18: =IF($A18=M$3,0,ROUND(SQRT((NodeData!$D18-NodeData!$D14)^2+(NodeData!$E18-NodeData!$E14)^2)/UAV_Params!$B$8+ABS(NodeData!$F18-NodeData!$F14)/UAV_Params!$B$9,1)) -> 26.2 | N18: =IF($A18=N$3,0,ROUND(SQRT((NodeData!$D18-NodeData!$D15)^2+(NodeData!$E18-NodeData!$E15)^2)/UAV_Params!$B$8+ABS(NodeData!$F18-NodeData!$F15)/UAV_Params!$B$9,1)) -> 20.6 | O18: =IF($A18=O$3,0,ROUND(SQRT((NodeData!$D18-NodeData!$D16)^2+(NodeData!$E18-NodeData!$E16)^2)/UAV_Params!$B$8+ABS(NodeData!$F18-NodeData!$F16)/UAV_Params!$B$9,1)) -> 19.9 | P18: =IF($A18=P$3,0,ROUND(SQRT((NodeData!$D18-NodeData!$D17)^2+(NodeData!$E18-NodeData!$E17)^2)/UAV_Params!$B$8+ABS(NodeData!$F18-NodeData!$F17)/UAV_Params!$B$9,1)) -> 3 | Q18: =IF($A18=Q$3,0,ROUND(SQRT((NodeData!$D18-NodeData!$D18)^2+(NodeData!$E18-NodeData!$E18)^2)/UAV_Params!$B$8+ABS(NodeData!$F18-NodeData!$F18)/UAV_Params!$B$9,1)) -> 0 | R18: =IF($A18=R$3,0,ROUND(SQRT((NodeData!$D18-NodeData!$D19)^2+(NodeData!$E18-NodeData!$E19)^2)/UAV_Params!$B$8+ABS(NodeData!$F18-NodeData!$F19)/UAV_Params!$B$9,1)) -> 10.3 | S18: =IF($A18=S$3,0,ROUND(SQRT((NodeData!$D18-NodeData!$D20)^2+(NodeData!$E18-NodeData!$E20)^2)/UAV_Params!$B$8+ABS(NodeData!$F18-NodeData!$F20)/UAV_Params!$B$9,1)) -> 14.1
A19: 15 | B19: B7-光伏棚支架松动 | C19: =IF($A19=C$3,0,ROUND(SQRT((NodeData!$D19-NodeData!$D4)^2+(NodeData!$E19-NodeData!$E4)^2)/UAV_Params!$B$8+ABS(NodeData!$F19-NodeData!$F4)/UAV_Params!$B$9,1)) -> 27.2 | D19: =IF($A19=D$3,0,ROUND(SQRT((NodeData!$D19-NodeData!$D5)^2+(NodeData!$E19-NodeData!$E5)^2)/UAV_Params!$B$8+ABS(NodeData!$F19-NodeData!$F5)/UAV_Params!$B$9,1)) -> 25.7 | E19: =IF($A19=E$3,0,ROUND(SQRT((NodeData!$D19-NodeData!$D6)^2+(NodeData!$E19-NodeData!$E6)^2)/UAV_Params!$B$8+ABS(NodeData!$F19-NodeData!$F6)/UAV_Params!$B$9,1)) -> 25.8 | F19: =IF($A19=F$3,0,ROUND(SQRT((NodeData!$D19-NodeData!$D7)^2+(NodeData!$E19-NodeData!$E7)^2)/UAV_Params!$B$8+ABS(NodeData!$F19-NodeData!$F7)/UAV_Params!$B$9,1)) -> 24.7 | G19: =IF($A19=G$3,0,ROUND(SQRT((NodeData!$D19-NodeData!$D8)^2+(NodeData!$E19-NodeData!$E8)^2)/UAV_Params!$B$8+ABS(NodeData!$F19-NodeData!$F8)/UAV_Params!$B$9,1)) -> 31.7 | H19: =IF($A19=H$3,0,ROUND(SQRT((NodeData!$D19-NodeData!$D9)^2+(NodeData!$E19-NodeData!$E9)^2)/UAV_Params!$B$8+ABS(NodeData!$F19-NodeData!$F9)/UAV_Params!$B$9,1)) -> 32.9 | I19: =IF($A19=I$3,0,ROUND(SQRT((NodeData!$D19-NodeData!$D10)^2+(NodeData!$E19-NodeData!$E10)^2)/UAV_Params!$B$8+ABS(NodeData!$F19-NodeData!$F10)/UAV_Params!$B$9,1)) -> 34.1 | J19: =IF($A19=J$3,0,ROUND(SQRT((NodeData!$D19-NodeData!$D11)^2+(NodeData!$E19-NodeData!$E11)^2)/UAV_Params!$B$8+ABS(NodeData!$F19-NodeData!$F11)/UAV_Params!$B$9,1)) -> 37.9 | K19: =IF($A19=K$3,0,ROUND(SQRT((NodeData!$D19-NodeData!$D12)^2+(NodeData!$E19-NodeData!$E12)^2)/UAV_Params!$B$8+ABS(NodeData!$F19-NodeData!$F12)/UAV_Params!$B$9,1)) -> 40 | L19: =IF($A19=L$3,0,ROUND(SQRT((NodeData!$D19-NodeData!$D13)^2+(NodeData!$E19-NodeData!$E13)^2)/UAV_Params!$B$8+ABS(NodeData!$F19-NodeData!$F13)/UAV_Params!$B$9,1)) -> 33.2 | M19: =IF($A19=M$3,0,ROUND(SQRT((NodeData!$D19-NodeData!$D14)^2+(NodeData!$E19-NodeData!$E14)^2)/UAV_Params!$B$8+ABS(NodeData!$F19-NodeData!$F14)/UAV_Params!$B$9,1)) -> 33.7 | N19: =IF($A19=N$3,0,ROUND(SQRT((NodeData!$D19-NodeData!$D15)^2+(NodeData!$E19-NodeData!$E15)^2)/UAV_Params!$B$8+ABS(NodeData!$F19-NodeData!$F15)/UAV_Params!$B$9,1)) -> 28.9 | O19: =IF($A19=O$3,0,ROUND(SQRT((NodeData!$D19-NodeData!$D16)^2+(NodeData!$E19-NodeData!$E16)^2)/UAV_Params!$B$8+ABS(NodeData!$F19-NodeData!$F16)/UAV_Params!$B$9,1)) -> 30.3 | P19: =IF($A19=P$3,0,ROUND(SQRT((NodeData!$D19-NodeData!$D17)^2+(NodeData!$E19-NodeData!$E17)^2)/UAV_Params!$B$8+ABS(NodeData!$F19-NodeData!$F17)/UAV_Params!$B$9,1)) -> 11.2 | Q19: =IF($A19=Q$3,0,ROUND(SQRT((NodeData!$D19-NodeData!$D18)^2+(NodeData!$E19-NodeData!$E18)^2)/UAV_Params!$B$8+ABS(NodeData!$F19-NodeData!$F18)/UAV_Params!$B$9,1)) -> 10.3 | R19: =IF($A19=R$3,0,ROUND(SQRT((NodeData!$D19-NodeData!$D19)^2+(NodeData!$E19-NodeData!$E19)^2)/UAV_Params!$B$8+ABS(NodeData!$F19-NodeData!$F19)/UAV_Params!$B$9,1)) -> 0 | S19: =IF($A19=S$3,0,ROUND(SQRT((NodeData!$D19-NodeData!$D20)^2+(NodeData!$E19-NodeData!$E20)^2)/UAV_Params!$B$8+ABS(NodeData!$F19-NodeData!$F20)/UAV_Params!$B$9,1)) -> 4.5
A20: 16 | B20: B7-屋顶围挡破损 | C20: =IF($A20=C$3,0,ROUND(SQRT((NodeData!$D20-NodeData!$D4)^2+(NodeData!$E20-NodeData!$E4)^2)/UAV_Params!$B$8+ABS(NodeData!$F20-NodeData!$F4)/UAV_Params!$B$9,1)) -> 30.2 | D20: =IF($A20=D$3,0,ROUND(SQRT((NodeData!$D20-NodeData!$D5)^2+(NodeData!$E20-NodeData!$E5)^2)/UAV_Params!$B$8+ABS(NodeData!$F20-NodeData!$F5)/UAV_Params!$B$9,1)) -> 27.8 | E20: =IF($A20=E$3,0,ROUND(SQRT((NodeData!$D20-NodeData!$D6)^2+(NodeData!$E20-NodeData!$E6)^2)/UAV_Params!$B$8+ABS(NodeData!$F20-NodeData!$F6)/UAV_Params!$B$9,1)) -> 23.5 | F20: =IF($A20=F$3,0,ROUND(SQRT((NodeData!$D20-NodeData!$D7)^2+(NodeData!$E20-NodeData!$E7)^2)/UAV_Params!$B$8+ABS(NodeData!$F20-NodeData!$F7)/UAV_Params!$B$9,1)) -> 25.9 | G20: =IF($A20=G$3,0,ROUND(SQRT((NodeData!$D20-NodeData!$D8)^2+(NodeData!$E20-NodeData!$E8)^2)/UAV_Params!$B$8+ABS(NodeData!$F20-NodeData!$F8)/UAV_Params!$B$9,1)) -> 34 | H20: =IF($A20=H$3,0,ROUND(SQRT((NodeData!$D20-NodeData!$D9)^2+(NodeData!$E20-NodeData!$E9)^2)/UAV_Params!$B$8+ABS(NodeData!$F20-NodeData!$F9)/UAV_Params!$B$9,1)) -> 29.2 | I20: =IF($A20=I$3,0,ROUND(SQRT((NodeData!$D20-NodeData!$D10)^2+(NodeData!$E20-NodeData!$E10)^2)/UAV_Params!$B$8+ABS(NodeData!$F20-NodeData!$F10)/UAV_Params!$B$9,1)) -> 36.5 | J20: =IF($A20=J$3,0,ROUND(SQRT((NodeData!$D20-NodeData!$D11)^2+(NodeData!$E20-NodeData!$E11)^2)/UAV_Params!$B$8+ABS(NodeData!$F20-NodeData!$F11)/UAV_Params!$B$9,1)) -> 40.6 | K20: =IF($A20=K$3,0,ROUND(SQRT((NodeData!$D20-NodeData!$D12)^2+(NodeData!$E20-NodeData!$E12)^2)/UAV_Params!$B$8+ABS(NodeData!$F20-NodeData!$F12)/UAV_Params!$B$9,1)) -> 36.7 | L20: =IF($A20=L$3,0,ROUND(SQRT((NodeData!$D20-NodeData!$D13)^2+(NodeData!$E20-NodeData!$E13)^2)/UAV_Params!$B$8+ABS(NodeData!$F20-NodeData!$F13)/UAV_Params!$B$9,1)) -> 36.4 | M20: =IF($A20=M$3,0,ROUND(SQRT((NodeData!$D20-NodeData!$D14)^2+(NodeData!$E20-NodeData!$E14)^2)/UAV_Params!$B$8+ABS(NodeData!$F20-NodeData!$F14)/UAV_Params!$B$9,1)) -> 32.9 | N20: =IF($A20=N$3,0,ROUND(SQRT((NodeData!$D20-NodeData!$D15)^2+(NodeData!$E20-NodeData!$E15)^2)/UAV_Params!$B$8+ABS(NodeData!$F20-NodeData!$F15)/UAV_Params!$B$9,1)) -> 31.2 | O20: =IF($A20=O$3,0,ROUND(SQRT((NodeData!$D20-NodeData!$D16)^2+(NodeData!$E20-NodeData!$E16)^2)/UAV_Params!$B$8+ABS(NodeData!$F20-NodeData!$F16)/UAV_Params!$B$9,1)) -> 34 | P20: =IF($A20=P$3,0,ROUND(SQRT((NodeData!$D20-NodeData!$D17)^2+(NodeData!$E20-NodeData!$E17)^2)/UAV_Params!$B$8+ABS(NodeData!$F20-NodeData!$F17)/UAV_Params!$B$9,1)) -> 13.9 | Q20: =IF($A20=Q$3,0,ROUND(SQRT((NodeData!$D20-NodeData!$D18)^2+(NodeData!$E20-NodeData!$E18)^2)/UAV_Params!$B$8+ABS(NodeData!$F20-NodeData!$F18)/UAV_Params!$B$9,1)) -> 14.1 | R20: =IF($A20=R$3,0,ROUND(SQRT((NodeData!$D20-NodeData!$D19)^2+(NodeData!$E20-NodeData!$E19)^2)/UAV_Params!$B$8+ABS(NodeData!$F20-NodeData!$F19)/UAV_Params!$B$9,1)) -> 4.5 | S20: =IF($A20=S$3,0,ROUND(SQRT((NodeData!$D20-NodeData!$D20)^2+(NodeData!$E20-NodeData!$E20)^2)/UAV_Params!$B$8+ABS(NodeData!$F20-NodeData!$F20)/UAV_Params!$B$9,1)) -> 0

Sheet FlightEnergy
A1: 节点间飞行能耗矩阵（焦耳）
A3: from_id | B3: from_name | C3: 0 | D3: 1 | E3: 2 | F3: 3 | G3: 4 | H3: 5 | I3: 6 | J3: 7 | K3: 8 | L3: 9 | M3: 10 | N3: 11 | O3: 12 | P3: 13 | Q3: 14 | R3: 15 | S3: 16
